Workbook

Sheet Cover
B2: E2 Scenario Justification & OCC Requirements
B5: Sub-activities 1, 2 & 3 of 3 — OCC (Defensive Driving) + TRF (Traffic Expectations) + SIG (Intention Signaling)
B7: Program | C7: DO-Crawl (I-35 Dallas–Laredo)
B8: Platform | C8: Class 8 AV Truck (SDT)
B9: ODD envelope | C9: 0–68 mph (0–30.4 m/s) limited-access highway
B10: Document | C10: E2_Scenario_Justification_v4.1.xlsx
B11: Scope | C11: OCC (QA-corrected) + TRF (initial draft) + SIG (initial draft). E2 livrable complet.
B12: Version | C12: v4.1 — OCC QA-corrected + TRF + SIG extensions (see E2_OCC_QA_Review_v1.0.docx)
B13: Date | C13: 2026-04-19
B14: Owner | C14: Neil Benhamou — FuSa/SOTIF Engineer
B15: Status | C15: Draft — OCC QA findings F-M-01..04, F-S-01..11, F-H-01..05 applied; TRF + SIG initial drafts for internal review.
B16: Standards touched | C16: ISO 21448:2022, ISO/DTS 5083, ISO/PAS 8800, ISO 26262, UN R157, UN R13 (ESS), FMVSS 108, FMCSA 49 CFR §§393.9/11/20/22, FHWA BC, Texas TRC §§545/547
B19: Color legend (per Torc/industry FA modelling convention)
B20: Blue | C20: Hardcoded inputs — numbers the user changes for scenarios
B21: Black | C21: Formulas and calculations
B22: Green | C22: Links to another worksheet in this workbook
B23: Red | C23: Links to external files
B24: Yellow | C24: Key assumption needing attention or confirmation
B27: Source verification tiers
B28: VERIFIED | C28: Direct reference to a regulatory text, published standard, or peer-reviewed paper the author holds a copy of
B29: DERIVED | C29: Number computed from other VERIFIED inputs via an explicit kinematic/physical equation documented in-sheet
B30: TBD/TBR | C30: Not yet sourced. Must be confirmed by Neil or the relevant Torc owner before release. Do NOT cite externally.
B33: Reviewer note
B34: All numeric inputs are traceable. Any cell with a yellow fill or a [TBD]/[TBR] label must be confirmed against the authoritative source (JAMA, Torc internal measurement campaign, or cited external document) before this file is used for a formal DSC gate review. The kinematic model implements the speed-dependent time-headway policy h(v) = max(h_floor, t_total + v/(2·a_SDT) − (L+g_h)/v) × (1 + m_safety), which is the basis for requirement OCC-002.

Sheet Actor Layer
A1: Actor Layer Assumptions — SDT, OMV, and environment
A3: Parameter | B3: Symbol | C3: Value | D3: Unit | E3: Tier | F3: Source / Rationale
A4: SDT max highway speed | B4: v_SDT_max | C4: 30.4 | D4: m/s | E4: VERIFIED | F4: 68 mph ODD ceiling (DO-Crawl ODD catalog). 68 mph × 0.44704.
A5: SDT free-flow reference speed | B5: v_SDT_ff | C5: 29 | D5: m/s | E5: DERIVED | F5: 65 mph × 0.44704 ≈ 29.06 m/s. Used for worst-case longitudinal kinematic sizing.
A6: SDT commanded deceleration (SDT) | B6: a_SDT | C6: 5 | D6: m/s² | E6: TBV | F6: Torc internal BiL test envelope for Class 8 loaded GCVW — upper-bound design value. [TBV with JAMA brake test report]. F-S-04 applied.
A7: Brake rise time (FMVSS 121) | B7: t_rise | C7: 0.45 | D7: s | E7: VERIFIED | F7: FMVSS 121 §S5.3.3 (Brake actuation time, 49 CFR 571.121) — air-brake system build-up delay for loaded Class 8. F-S-07 applied.
A8: ADS detect-to-brake reaction time | B8: t_react | C8: 0.7 | D8: s | E8: TBV | F8: Torc internal ADS BiL envelope (perception + decision + actuation hand-off). [Prior citation SAE J3018 retracted — J3018 scope is In-Vehicle Fallback Test Driver, not ADS reaction time]. F-S-04 applied.
A9: Total end-to-end system delay | B9: t_total | C9: 1.15 | D9: s | E9: DERIVED | F9: t_react + t_rise = 0.70 + 0.45 = 1.15 s.
A10: Semi-trailer length (SDT) | B10: L_semi | C10: 16 | D10: m | E10: TBV | F10: 23 CFR §658.13 (STAA dimensions) — 48 ft trailer ≈ 14.6 m + tractor porte-à-faux. Total vehicle length can reach ~20 m. Value 16 m = trailer + tractor fifth-wheel zone [TBV Torc fleet engineering]. F-S-01 applied.
A11: Double-trailer length | B11: L_double | C11: 28 | D11: m | E11: TBV | F11: 23 CFR §658.13 — 28 ft + 28 ft trailers = 17.1 m of trailers; with tractor ~23–25 m. Value 28 m = upper-bound engineering estimate [TBV]. F-S-01 applied.
A12: OMV hard-brake deceleration | B12: a_OMV | C12: 12 | D12: m/s² | E12: TBV | F12: Torc conservative hypothesis for panic-stop OMV on high-μ surface with performant ABS — envelope above UN R157 baseline (≈6 m/s²). [Exact UN R157 Annex 4 clause to be verified in UNECE ECE/TRANS/WP.29/2020/81]. F-S-05 applied.
A13: OMV standard deceleration (free-flow) | B13: a_OMV_ff | C13: 5 | D13: m/s² | E13: DERIVED | F13: Symmetric braking hypothesis with a_SDT. Consistent with Wang, Xu & Dai (2019) AAP 124:127-137 naturalistic driving envelope [TBV p95 value]. F-S-11 applied.
A14: Minimum lateral cut-in gap (physical) | B14: g_h_min | C14: 0 | D14: m | E14: VERIFIED | F14: UN R157 Annex 4 (ALKS cut-in safety demonstration) — aggressive cut-in with zero effective longitudinal headway, worst-case kinematic sizing. [TBV exact clause].
A15: Typical cut-in vehicle length | B15: L_CIV | C15: 5 | D15: m | E15: VERIFIED | F15: FHWA passenger-car class, standard mid-size sedan.
... A22: Free-flow / congestion speed threshold | B22: v_thr | C22: 20 | D22: m/s | E22: TBV | F22: Torc conservative threshold for free-flow vs congestion regime (45 mph). Below this, h_floor dominates and cut-in kinematics are manageable. Choice lower than HCM 2016 LOS D vertex (≈28 m/s for FFS=70 mph) for safety margin — NOT derived directly from HCM. [TBV by traffic engineering]. F-S-08 applied.
A24: TRF sub-activity — Traffic Expectations parameters
A25: Lane-change signal lead time | B25: t_LC_signal | C25: 3 | D25: s | E25: TBV | F25: Industry practice for ADS Class 8 (SAE J3016 intent-signalling guidance). Texas TRC §545.104 prescribes 100 ft minimum before turn/change — at 29 m/s ≈ 1 s, ADS adopts ≥3 s lead for predictability to other drivers. [TBV internal Torc HMI spec].
A26: Minimum signal-to-maneuver distance | B26: d_signal_min | C26: 30 | D26: m | E26: VERIFIED | F26: Texas TRC §545.104(b) — signal at least 100 ft (≈30 m) before turn, stop, or lane change.
A27: Max longitudinal jerk (nominal) | B27: j_long_max | C27: 2 | D27: m/s³ | E27: DERIVED | F27: UN R157 §5.6.2 smooth-driving envelope for ALKS; aligned with industry ride-comfort limit (~2 m/s³) — [TBV Torc longitudinal controller calibration].
A28: Max longitudinal jerk (emergency) | B28: j_long_emerg | C28: 5 | D28: m/s³ | E28: DERIVED | F28: UN R157 §5.6.2 emergency upper bound; [TBV field validation].
A29: Max lateral jerk | B29: j_lat_max | C29: 1.5 | D29: m/s³ | E29: DERIVED | F29: ISO 11270 heading-control comfort guidance; [TBV Torc lateral controller].
A30: Posted speed — upper tolerance | B30: dv_posted_up | C30: 1.34 | D30: m/s | E30: TBV | F30: ADS speed compliance band: target ≤ posted + 3 mph to remain lawful yet cohérent with flow. [TBV Torc policy].
A31: Posted speed — lower tolerance | B31: dv_posted_low | C31: 2.24 | D31: m/s | E31: TBV | F31: ADS speed compliance band: target ≥ posted − 5 mph to avoid rolling roadblock. [TBV Torc policy].
A32: Flow-match delta below 85th pctl | B32: dv_flow | C32: 5 | D32: m/s | E32: TBV | F32: Maximum tolerated slow-down below traffic 85th percentile speed before accepting non-flow-match. [TBV traffic engineering].
A33: Minimum highway speed (legal floor) | B33: v_min | C33: 17.9 | D33: m/s | E33: VERIFIED | F33: Texas TRC §545.351(b) — 40 mph minimum on Interstate unless hazard, gradient, or law-enforcement direction.
A34: Gap target for on-ramp merger | B34: t_gap_merger | C34: 1.5 | D34: s | E34: TBV | F34: Minimum time-gap offered to an on-ramp merging vehicle; derived from AAA Foundation merge-behavior studies [TBV].
A35: Zipper-merge gap | B35: t_gap_zipper | C35: 1 | D35: s | E35: TBV | F35: Minimum time-gap in alternating zipper-merge; MUTCD 2023 Part 6C TTC + FHWA late-merge guidance [TBV].
A36: Move-over lateral clearance | B36: d_moveover | C36: 1.2 | D36: m | E36: VERIFIED | F36: Texas TRC §545.157(b) — pass emergency/stationary authorized vehicle with full lane change if possible, else reduce speed and increase lateral clearance.
... A42: Work-zone speed reduction | B42: dv_WZ | C42: 4.47 | D42: m/s | E42: VERIFIED | F42: MUTCD 2023 Part 6C — 10 mph posted reduction through active work zones.
A44: SIG sub-activity — Intention Signaling parameters
A45: Turn signal lead time (LC/exit) | B45: t_sig_lead | C45: 3 | D45: s | E45: TBV | F45: ADS intent-signaling lead time for lane change / exit. Texas TRC §545.104(b) prescribes 100 ft (~1 s at 29 m/s); ADS adopts ≥3 s for Class 8 predictability [TBV Torc HMI spec].
A46: Turn signal min lead distance | B46: d_sig_lead | C46: 30 | D46: m | E46: VERIFIED | F46: Texas TRC §545.104(b) — minimum 100 ft (30.48 m) signal before a turn, stop, or lane change.
A47: Turn signal min display before LC | B47: t_sig_min_pre | C47: 2 | D47: s | E47: TBV | F47: Minimum signal time before lateral commitment begins. Below this, signal is perceived as 'signal-after-intent' by other drivers. [TBV Torc HMI calibration].
A48: Turn signal auto-off tolerance | B48: t_sig_auto_off | C48: 1 | D48: s | E48: DERIVED | F48: Max delay between end of lateral maneuver (heading aligned with new lane) and signal-off command. Avoids 'blinker-left-on' confusion.
A49: Turn signal flash frequency | B49: f_sig_flash | C49: 1.5 | D49: Hz | E49: VERIFIED | F49: FMVSS 108 S7.8.5 — 60 to 120 flashes per minute (1.0 to 2.0 Hz). Nominal 90/min = 1.5 Hz.
A50: Brake light min display duration | B50: t_brk_min | C50: 0.3 | D50: s | E50: DERIVED | F50: Minimum brake-lamp ON duration even for very short decel transients. Below 0.3 s not perceivable by following drivers. UN R48 §6.7 ref.
A51: Progressive brake light threshold | B51: a_brk_on | C51: 0.5 | D51: m/s² | E51: VERIFIED | F51: FMVSS 108 / UN R13H — brake lamps shall come on when service brake is applied (typical 0.5 m/s² deceleration threshold for ADS, mapped to brake pedal travel / pressure).
A52: ESS activation decel threshold | B52: a_ess_on | C52: 6 | D52: m/s² | E52: VERIFIED | F52: UN R13 §5.2.1.31 (Emergency Stop Signal) — flashing brake lamps triggered when deceleration ≥ 6 m/s² (0.6 g). Activation recommended, mandatory in UN R13H §5.2.22.
A53: ESS / hazard flash frequency | B53: f_ess_flash | C53: 4 | D53: Hz | E53: VERIFIED | F53: UN R13 §5.2.1.31.3 — ESS flashing frequency 4.0 ± 1.0 Hz (240 ± 60 per minute).
A54: ESS deactivation decel threshold | B54: a_ess_off | C54: 2.5 | D54: m/s² | E54: VERIFIED | F54: UN R13 §5.2.1.31.2 — ESS deactivated when decel < 2.5 m/s² or when brake lamps normal.
...

Sheet Scenario Catalog
A1: OCC Scenario Catalog — Sub-activity 1 (Defensive Driving in Occlusion Areas)
A3: ID | B3: Family | C3: Scenario name | D3: Regime | E3: Trigger | F3: Occluding actor | G3: Primary hazard | H3: Governing equation | I3: Temporal description (phase by phase) | J3: Governed requirement(s) | K3: Source/References
A4: OCC-A1 | B4: A — Longitudinal (cut-out) | C4: Semi-trailer cut-out reveals stopped vehicle | D4: Free-flow | E4: Lead semi-trailer changes lane unveiling stopped vehicle | F4: Semi-trailer (L=16 m) | G4: Longitudinal (rear-end stopped) | H4: h_min(v)=v/(2·a_SDT)+t_total−(L+g_h)/v | I4: ROAD: 2-lane I-35 southbound, straight, level. GEOMETRY CONVENTION: d measured from SDT front. SDT follows OMV at h_policy(29,L=16) = 4.37 s → d_OMV_rear = 126.8 m, d_OMV_front = 142.8 m. t=−5s SETUP: SDT in RL at v=29 m/s. OMV semi-trailer (L=16 m) in RL at d_OMV_rear=+127 m, v=29 m/s. Stopped car occluded ahead of OMV at d_car = d_OMV_front + g_h = 143 m (g_h=0). LL clear. t=−3s→−0.5s CUT-OUT INTENT: OMV activates left turn signal, lateral v=0.5 m/s. SDT perception flags intent (OCC-003). t=0 REVEAL: OMV fully in LL. Stopped car exposed to SDT at d=+143 m, Δv=29 m/s. t=0→+1.15s SYSTEM DELAY: SDT covers 33.4 m at constant 29 m/s → gap shrinks to 109.5 m. Brake command issued at t=1.15s. t=+1.15s→+6.95s BRAKING: SDT decels at 5 m/s², stopping distance 84.1 m → final margin ≈ 25.4 m. OUTCOME: collision avoided with comfortable margin. Worst-case sensitivity (a_SDT=4.5 m/s² degraded): stopping 93.4 m → margin 16.1 m, still above 5 m critical floor. F-M-01 applied. | J4: OCC-001,002,003,008 | K4: UN R157 §5.1; AASHTO SSD Table 3-1
A5: OCC-A2 | B5: A — Longitudinal (cut-out) | C5: Double-trailer cut-out reveals slow vehicle | D5: Free-flow | E5: Double trailer cut-out; lead vehicle ~15 m/s behind | F5: Double trailer (L=28 m) | G5: Longitudinal (speed mismatch) | H5: Same as OCC-A1 with L=28 m | I5: ROAD: 2-lane I-35 southbound, straight, level. GEOMETRY CONVENTION: d measured from SDT front. SDT follows OMV double at h_policy(29,L=28) = 3.86 s → d_OMV_rear = +112 m, d_OMV_front = +140 m. t=−5s SETUP: SDT in RL at v=29 m/s. OMV double-trailer (L=28 m) in RL at d_OMV_rear=+112 m, v=29 m/s. Slow pickup (L=5 m) in front of OMV at d_pickup = d_OMV_front + g_h = +140 m (g_h=0), v_slow=14 m/s. LL clear. t=−3s→−0.5s CUT-OUT INTENT: OMV double begins left lane change, turn signal on, lateral v=0.5 m/s. t=0 REVEAL: slow pickup exposed at d=+140 m, Δv=15 m/s. t=0→+1.15s SYSTEM DELAY: SDT covers 33.4 m, pickup covers 16.1 m → gap = 140 + 16.1 − 33.4 = 122.7 m. t=+1.15s→+~4.15s BRAKING & CONVERGENCE: SDT decels at 5 m/s² toward v=14 m/s (matches in 3 s; SDT covers 64.5 m; pickup covers 42 m). Final gap ≈ 122.7 + 42 − 64.5 = 100.2 m (large margin because slow pickup keeps moving). OUTCOME: avoided; steady-state following at h_policy(14)=2.5 s → gap 35 m. F-M-01 applied. | J5: OCC-001,002,003 | K5: 23 CFR §658.13 (STAA dims); Wang 2019
A6: OCC-A3 | B6: A — Longitudinal (cut-out) | C6: Flatbed cut-out reveals debris | D6: Free-flow | E6: Flatbed changes lane; static debris revealed | F6: Flatbed (L=16 m) | G6: Static obstacle emergence | H6: h_min same; debris = stopped obstacle | I6: ROAD: 2-lane I-35 southbound, straight, level. GEOMETRY CONVENTION: d measured from SDT front. SDT follows OMV at h_policy(29,L=16) = 4.37 s → d_OMV_rear = +127 m, d_OMV_front = +143 m. t=−5s SETUP: SDT in RL at v=29 m/s. OMV flatbed (L=16 m) in RL at d_OMV_rear=+127 m, v=29 m/s. Static debris (tire, 0.6 m) on RL pavement at d_debris = d_OMV_front + g_h = +143 m (g_h=0). LL clear. t=−3s→−0.5s CUT-OUT INTENT: flatbed turn signal + lateral v=0.5 m/s. t=0 REVEAL: debris exposed at d=+143 m — small RCS, low contrast. Perception stress (OCC-001 horizon ≥ 1.5·SSD). t=0→+1.15s SYSTEM DELAY: SDT covers 33.4 m → gap 109.6 m. t=+1.15s→+6.95s BRAKING: SDT full stop in 84.1 m → margin 25.5 m. OUTCOME: avoided if debris classified ≤ +0.3 s after reveal; otherwise degraded mode (OCC-013 perception curtain). F-M-01 applied. | J6: OCC-001,003,008,013 | K6: AASHTO SSD; FHWA debris studies [TBV]
A7: OCC-A4 | B7: A — Longitudinal (cut-out) | C7: Convoy cut-out cascade | D7: Free-flow | E7: Multiple occluding actors in echelon cut-out | F7: Convoy of 2–3 trucks | G7: Repeated reveal — cascaded braking | H7: h_min sized on worst of cascade | I7: ROAD: 2-lane I-35, straight, level. t=−6s SETUP: SDT in RL at v=29 m/s. Two OMV semis in RL column: OMV1 at d=+127 m, OMV2 at d=+153 m (intra-convoy gap 10 m). Slow vehicle (v=10 m/s) in RL at d=+170 m, hidden by OMV2. LL clear. t=−4s CUT-OUT#1: OMV1 changes to LL. t=−2.5s CUT-OUT#2: OMV2 begins lane change 1.5 s after OMV1. t=0 DOUBLE REVEAL: OMV1 clear, OMV2 straddling RL/LL, slow vehicle at d≈+135 m partially exposed. t=0→+2s SDT treats cascade as single envelope (OCC-004): holds h_policy on tail of convoy. t=+2s→+~8s BRAKING: SDT decels progressively toward v_slow=10 m/s. OUTCOME: avoided; follows slow vehicle at h_policy(10)=2.5 s → gap 25 m. | J7: OCC-001,002,004 | K7: Torc scenario library WIP [TBV]
A8: OCC-A5 | B8: A — Longitudinal (cut-out) | C8: Slow-mover (maintenance/tractor) revealed | D8: Transition | E8: Slow-mover ≤ 10 m/s dévoilé; v_rel ≥ 19 m/s | F8: Truck/pickup (L=16 m) | G8: High v_rel rear-end | H8: Same, Δv=v_SDT−v_slow | I8: ROAD: 2-lane I-35 southbound, straight, level, near exit to farm road. GEOMETRY CONVENTION: d measured from SDT front. SDT follows OMV at h_policy(29,L=16) = 4.37 s → d_OMV_rear = +127 m, d_OMV_front = +143 m. t=−5s SETUP: SDT in RL at v=29 m/s. OMV semi (L=16 m) in RL at d_OMV_rear=+127 m, v=29 m/s. Agricultural tractor (L=5 m, v=7 m/s) hidden behind OMV at d_tractor_rear = d_OMV_front + g_h = +143 m (g_h=0). LL clear. t=−3s CUT-OUT INTENT: OMV signal + lateral v=0.5 m/s. t=0 REVEAL: tractor exposed at d=+143 m, Δv=22 m/s. t=0→+1.15s SYSTEM DELAY: SDT covers 33.4 m, tractor covers 8 m → gap = 143 + 8 − 33.4 = 117.6 m. t=+1.15s→+~5.55s BRAKING: SDT decels at 5 m/s² toward v=7 m/s (converges in 4.4 s; SDT covers 79.2 m; tractor covers 30.8 m). Final gap ≈ 117.6 + 30.8 − 79.2 = 69.2 m. OUTCOME: avoided; follows tractor at h_policy(7)=2.5 s → gap 17.5 m. F-M-01 applied. | J8: OCC-001,002,003 | K8: Texas TRC §545.351; Torc ODD
A9: OCC-B1 | B9: B — Cut-in | C9: Standard cut-in, gap respected | D9: Free-flow | E9: Adjacent-lane vehicle merges keeping gap ≥ 2 s | F9: Passenger car (L=5 m) | G9: Minor headway erosion | H9: Adjust h by closing Δv | I9: ROAD: 2-lane I-35, straight, level, no leading vehicle in RL. t=−3s SETUP: SDT in RL at v=29 m/s. Passenger car V_cut (L=5 m) in LL at d=+40 m, v=27 m/s. t=−2s INTENT: V_cut right turn signal, lateral v=0.3 m/s, monitoring adjacent gap. t=0 INTRUSION: V_cut crosses RL boundary at effective headway ≥ 2 s (~54 m ahead of SDT). t=0→+0.3s DETECTION: SDT flags cut-in (OCC-005, lateral-v ≥ 0.3 m/s + TTI-lane ≤ 2 s). t=+0.3s→+~8s ADJUSTMENT: SDT decels lightly (~1 m/s²) toward the policy following state. Target headway h_policy(27,L=5) = MAX(h_floor, 3.665)×1.25 = 4.58 s → gap 4.58×27 ≈ 124 m. OUTCOME: nominal following re-established; no hazard. F-M-03 applied (h_policy recomputed with L and m_safety). | J9: OCC-002,005 | K9: UN R157 Annex 4 §3.1 normal case
A10: OCC-B2 | B10: B — Cut-in | C10: Cut-in + moderate brake (5 m/s²) | D10: Free-flow | E10: Cut-in vehicle decelerates after merge | F10: Passenger car (L=5 m) | G10: Headway erosion + speed drop | H10: h_min(v,a_OMV=5) | I10: ROAD: 2-lane I-35, straight, level. t=−3s SETUP: SDT in RL at v=29 m/s, V_cut (passenger car, L=5 m) in LL at d=+40 m, v=27 m/s. t=−2s INTENT: V_cut right turn signal, lateral v=0.4 m/s. t=0 INTRUSION: V_cut at d=+54 m (~2 s headway) in RL. t=0→+0.3s DETECTION: SDT flags cut-in. t=+0.3s BRAKE START (V_cut): V_cut applies moderate 5 m/s² brake. t=+0.3s→+~3.3s SDT matches deceleration (5 m/s²), closes Δv progressively. Relative Δv peaks, then converges. Nominal worst gap ≈ 24 m (h≈1.5 s — brief excursion below h_policy). OUTCOME: avoided; post-event h re-climbs to h_policy at new common speed. | J10: OCC-002,005,006 | K10: Wang 2019 NDS p95; highD (Krajewski 2018)
A11: OCC-B3 | B11: B — Cut-in | C11: Aggressive cut-in + hard brake — FREE-FLOW | D11: Free-flow | E11: v=29 m/s, g_h=0, a_OMV=12 m/s² | F11: Passenger car (L=5 m) | G11: Kinematically unavoidable impact | H11: Collision detected; residual risk | I11: ROAD: 2-lane I-35, straight, level, FREE-FLOW regime (v ≥ v_thr=20 m/s). t=−1s SETUP: SDT in RL at v=29 m/s. V_cut (passenger car, L=5 m) in LL at adjacent longitudinal offset, v=27 m/s. Aggressive/distracted driver. t=−0.5s ABRUPT STEER: V_cut lateral v=1.2 m/s, NO turn signal. t=0 INTRUSION COMPLETE: V_cut in RL at d_initial = +20 m (SDT-front to V_cut-rear), v=27 m/s. Simultaneously applies hard brake a_OMV=12 m/s². t=0→+1.15s SYSTEM DELAY: SDT cruises at 29 m/s → covers 33.35 m. V_cut decels: covers 27·1.15 − 0.5·12·1.15² = 31.05 − 7.94 = 23.1 m, v reaches 27 − 12·1.15 = 13.2 m/s. Instantaneous gap: 20 + 23.1 − 33.35 = 9.75 m, Δv = 29 − 13.2 = 15.8 m/s. t=+1.15s→t_impact BRAKE ENGAGED: SDT decels 5 m/s². Solving x_SDT(t)=x_Vcut(t): 29t = 20 + 27t − 6t² ⇒ t_impact ≈ 1.67 s (V_cut still braking; v_Vcut = 7 m/s). SDT v ≈ 26.4 m/s at impact → Δv_impact ≈ 19.4 m/s. OUTCOME: KINEMATICALLY UNAVOIDABLE under E2 boundary conditions (residual SOTIF risk, ISO 21448 §7). Brake does engage for ≈0.52 s prior to impact (not 'never applies'). OCC-014 mitigates via low-visibility / low-speed curtain when ambient permits; field monitoring required. F-M-04 applied (brake engagement documented, Δv ≈ 19.4 m/s corrected). | J11: OCC-006,014 | K11: UN R157 Annex 4 §3.1; Vass et al. 2026 [TBV]
A12: OCC-B4 | B12: B — Cut-in | C12: Aggressive cut-in + hard brake — CONGESTION | D12: Congestion | E12: v ≤ 20 m/s, g_h ≈ h_floor·v, a_OMV=12 m/s² | F12: Passenger car (L=5 m) | G12: Manageable headway erosion | H12: h_min(v,a_OMV=12) ≤ h_floor | I12: ROAD: 2-lane I-35, straight, level, CONGESTION regime (start of traffic jam, v < v_thr=20 m/s). t=−3s SETUP: SDT in RL at v=15 m/s following existing lead at h_policy=2.5 s → gap 37.5 m. V_cut (passenger car, L=5 m) in LL at adjacent longitudinal position, v=14 m/s. t=−0.5s ABRUPT STEER: V_cut lateral v=1.2 m/s into RL in front of SDT. t=0 INTRUSION: V_cut enters at d=+37.5 m (geometric floor imposed by congestion traffic), v=15 m/s, immediately applies 12 m/s². t=0→+1.15s SYSTEM DELAY: SDT at 15 m/s covers 17.25 m; V_cut decels to rest at t=1.25 s covering 9.375 m → gap = 37.5 + 9.375 − 17.25 = 29.6 m. t=+1.15s→+4.15s BRAKING: SDT decels 5 m/s², covers 22.5 m, stops. V_cut at 46.875 m. Final margin ≈ 7.1 m. OUTCOME: avoided with margin. Demonstrates manageability in CONGESTION regime (OCC-006). | J12: OCC-002,006 | K12: HCM 2016 Ch.12 LOS D
A13: OCC-B5 | B13: B — Cut-in | C13: Forced cut-in from blocked lane (work-zone merge) | D13: Either | E13: Lane-drop/merge forcing adjacent vehicle across | F13: Passenger car or truck | G13: Reduced gap, unpredictable Δv | H13: h_min(v,a_OMV) w/ warning boost | I13: ROAD: I-35 with active work-zone — RL closed 500 m ahead, HD-map flagged. t=−6s SETUP: SDT in RL at v=25 m/s, approaching LL-merge-required segment. OMV (truck, L=16 m) in LL at d=+60 m, v=25 m/s. Cones start 500 m ahead. t=−5s OCC-007 TRIGGER: HD-map reads WZ-ahead → SDT pre-reduces to 22 m/s, adds +0.5 s to h. t=−2s INTENT: adjacent vehicle V_cut (LL) detects RL cones and initiates forced cut-in toward RL/merging area. t=0 INTRUSION: V_cut enters ahead of SDT at g_h=8 m, v=24 m/s. t=0→+0.3s DETECTION + GAP CREATION: SDT decels 3 m/s² to offer merge space. t=+0.3s→+~3s CONVERGENCE: both settle at WZ speed ≈18 m/s with h_policy(18)=2.5 s. OUTCOME: avoided; WZ traversal completed at posted speed. | J13: OCC-005,006,007,011 | K13: MUTCD 2023 Part 6C (TTC)
A14: OCC-C1 | B14: C — Geometric | C14: Vertical crest (limited SSD) | D14: Free-flow | E14: Crest reduces geometric sight distance | F14: Road geometry | G14: Unseen stopped/slow vehicle | H14: SSD ≥ v²/(2·a_SDT)+v·t_total | I14: ROAD: I-35, 2-lane, crest vertical curve K=193 (AASHTO Table 3-34, sight-distance-limiting). Grade +3 % → −3 %. t=−4s SETUP: SDT in RL at v=29 m/s ascending grade. Stopped vehicle (broken down) 190 m past crest in RL. SSD at 65 mph = 195 m. t=0 CREST ENTRY: SDT crosses apex; line-of-sight opens from 0 to geometric limit. Stopped vehicle exposed at d=+190 m. t=0→+1.15s SYSTEM DELAY: SDT covers 33.4 m → gap 156.6 m. t=+1.15s→+6.95s BRAKING: SDT decels 5 m/s², covers 84.1 m → margin 72.5 m. OUTCOME: avoided, margin generous. OCC-008 enforces v ≤ v_max(SSD_geom − 10 m) preventively. | J14: OCC-008,009 | K14: AASHTO Green Book 2018 Table 3-34, K=193
... A25: OCC-E4 | B25: E — Environmental | C25: Sun glare / tunnel entry-exit | D25: Either | E25: Low-angle sun or rapid luminance change at tunnel | F25: Luminance step | G25: Transient blindness of sensor | H25: v_curtain < v_SDT during δt | I25: ROAD: I-35, transitioning from tunnel to daylight (western portal). t=−3s SETUP: SDT in RL at v=25 m/s inside tunnel (low-light). Sun at low angle beyond tunnel exit, expected 90 klux glare. t=−1s OCC-014 TRIGGER: HD-map flags tunnel portal within 100 m; SDT reduces to 22 m/s. t=0 EXIT: SDT emerges. Camera exposure transient ~0.3 s (blinding); lidar and radar maintain track. Stopped vehicle in RL at d=+150 m (previously just out of sensor effective range at portal). t=0→+0.3s CAMERA BLIND, RADAR/LIDAR OK: fusion downgrades camera weight. Vehicle detected by radar. t=+0.3s→+1.45s SYSTEM DELAY: covers 32 m → gap 118 m. t=+1.45s→+5.85s BRAKING: decels 5 m/s², covers 48.4 m → margin 69.6 m. OUTCOME: avoided; sensor-fusion complementarity handles glare. | J25: OCC-013,014 | K25: DO-Crawl ODD (sun glare / tunnel portal)

Sheet Kinematic Calc
A1: Kinematic Calculator — h(v) forward-chain equation
A3: Equation
A4: h_min(v) = v/(2·a_SDT) + t_total − (L + g_h)/v
A5: h_policy(v) = MAX(h_floor, h_min(v)) × (1 + m_safety)
A7: Inputs (link to 'Actor Layer')
A8: v (SDT speed) | B8: 29 | C8: m/s | D8: Free-flow highway 65 mph
A9: a_SDT (SDT decel) | B9: ='Actor Layer'!C6 -> 5 | C9: m/s² | D9: Link to Actor Layer — a_SDT
A10: t_total (system delay) | B10: ='Actor Layer'!C9 -> 1.15 | C10: s | D10: Link to Actor Layer — t_total
A11: L (occluding actor length) | B11: 16 | C11: m | D11: 16 m semi / 28 m double
A12: g_h (init longitudinal gap) | B12: 0 | C12: m | D12: Worst case g_h=0 for cut-in; >0 for cut-out
A13: a_OMV (OMV hard brake) | B13: ='Actor Layer'!C12 -> 12 | C13: m/s² | D13: Link — a_OMV
A14: h_floor (min headway) | B14: ='Actor Layer'!C21 -> 2 | C14: s | D14: Link — h_floor (2 s)
A15: m_safety (engineering margin) | B15: ='Actor Layer'!C20 -> 0.25 | C15: — | D15: Link — 25 %
A17: Outputs
A18: h_min_v (physical headway, s) | B18: =B8/(2*B9)+B10-(B11+B12)/B8 -> 3.4982759 | D18: Physical-limit time headway so that (SDT fully braked at impact OR (L+g_h) covered before impact)
A19: h_policy (applied headway, s) | B19: =MAX(B14, B18)*(1+B15) -> 4.3728448 | D19: MAX(h_floor, h_min) × (1 + m_safety) — this is the number propagated to OCC-002 policy.
A20: d_gap_min (m) at v | B20: =B8*B19 -> 126.8125 | D20: v × h_policy — minimum SDT-OMV gap to support h_policy.
A22: Regime diagnostic (cut-in hard-brake scenario)
A23: v_thr (threshold, m/s) | B23: ='Actor Layer'!C22 -> 20
A24: Current regime | B24: =IF(B8>=B23,"FREE-FLOW — residual risk (cf. OCC-014)","CONGESTION — manageable (cf. OCC-006)") -> FREE-FLOW — residual risk (cf. OCC-014)
A26: Worst-case cut-in survival (a_OMV=12, g_h=0)
A27: v_SDT_brake_to_rest (m/s at TTI) | B27: =MAX(0, B8 - B9*B19) -> 7.1357759
A28: Collision avoided? | B28: =IF(B27<=0,"YES — SDT fully stopped","NO — residual Δv at impact") -> NO — residual Δv at impact

Sheet Headway Envelope
A1: h(v) policy envelope — OCC-002 continuous function
A3: Constants (links)
A4: a_SDT | B4: ='Actor Layer'!C6 -> 5
A5: t_total | B5: ='Actor Layer'!C9 -> 1.15
A6: L (semi) | B6: ='Actor Layer'!C10 -> 16
A7: g_h (worst) | B7: 0
A8: h_floor | B8: ='Actor Layer'!C21 -> 2
A9: m_safety | B9: ='Actor Layer'!C20 -> 0.25
A10: v_thr | B10: ='Actor Layer'!C22 -> 20
A12: v (mph) | B12: v (m/s) | C12: h_min(v) — semi (s) | D12: h_policy(v) — semi (s) | E12: d_gap — semi (m) | F12: h_min(v) — double (s) | G12: h_policy(v) — double (s) | H12: d_gap — double (m) | I12: Regime
A13: 10 | B13: =A13*0.44704 -> 4.4704 | C13: =IFERROR(B13/(2*$B$4)+$B$5-($B$6+$B$7)/B13,"") -> -1.9820581 | D13: =IFERROR(MAX($B$8,C13)*(1+$B$9),"") -> 2.5 | E13: =IFERROR(B13*D13,"") -> 11.176 | F13: =IFERROR(B13/(2*$B$4)+$B$5-(28+$B$7)/B13,"") -> -4.6663816 | G13: =IFERROR(MAX($B$8,F13)*(1+$B$9),"") -> 2.5 | H13: =IFERROR(B13*G13,"") -> 11.176 | I13: =IF(B13>=$B$10,"FREE-FLOW","CONGESTION") -> CONGESTION
A14: 15 | B14: =A14*0.44704 -> 6.7056 | C14: =IFERROR(B14/(2*$B$4)+$B$5-($B$6+$B$7)/B14,"") -> -0.56550538 | D14: =IFERROR(MAX($B$8,C14)*(1+$B$9),"") -> 2.5 | E14: =IFERROR(B14*D14,"") -> 16.764 | F14: =IFERROR(B14/(2*$B$4)+$B$5-(28+$B$7)/B14,"") -> -2.3550544 | G14: =IFERROR(MAX($B$8,F14)*(1+$B$9),"") -> 2.5 | H14: =IFERROR(B14*G14,"") -> 16.764 | I14: =IF(B14>=$B$10,"FREE-FLOW","CONGESTION") -> CONGESTION
A15: 20 | B15: =A15*0.44704 -> 8.9408 | C15: =IFERROR(B15/(2*$B$4)+$B$5-($B$6+$B$7)/B15,"") -> 0.25453097 | D15: =IFERROR(MAX($B$8,C15)*(1+$B$9),"") -> 2.5 | E15: =IFERROR(B15*D15,"") -> 22.352 | F15: =IFERROR(B15/(2*$B$4)+$B$5-(28+$B$7)/B15,"") -> -1.0876308 | G15: =IFERROR(MAX($B$8,F15)*(1+$B$9),"") -> 2.5 | H15: =IFERROR(B15*G15,"") -> 22.352 | I15: =IF(B15>=$B$10,"FREE-FLOW","CONGESTION") -> CONGESTION
A16: 25 | B16: =A16*0.44704 -> 11.176 | C16: =IFERROR(B16/(2*$B$4)+$B$5-($B$6+$B$7)/B16,"") -> 0.83596077 | D16: =IFERROR(MAX($B$8,C16)*(1+$B$9),"") -> 2.5 | E16: =IFERROR(B16*D16,"") -> 27.94 | F16: =IFERROR(B16/(2*$B$4)+$B$5-(28+$B$7)/B16,"") -> -0.23776865 | G16: =IFERROR(MAX($B$8,F16)*(1+$B$9),"") -> 2.5 | H16: =IFERROR(B16*G16,"") -> 27.94 | I16: =IF(B16>=$B$10,"FREE-FLOW","CONGESTION") -> CONGESTION
A17: 30 | B17: =A17*0.44704 -> 13.4112 | C17: =IFERROR(B17/(2*$B$4)+$B$5-($B$6+$B$7)/B17,"") -> 1.2980873 | D17: =IFERROR(MAX($B$8,C17)*(1+$B$9),"") -> 2.5 | E17: =IFERROR(B17*D17,"") -> 33.528 | F17: =IFERROR(B17/(2*$B$4)+$B$5-(28+$B$7)/B17,"") -> 0.40331279 | G17: =IFERROR(MAX($B$8,F17)*(1+$B$9),"") -> 2.5 | H17: =IFERROR(B17*G17,"") -> 33.528 | I17: =IF(B17>=$B$10,"FREE-FLOW","CONGESTION") -> CONGESTION
A18: 35 | B18: =A18*0.44704 -> 15.6464 | C18: =IFERROR(B18/(2*$B$4)+$B$5-($B$6+$B$7)/B18,"") -> 1.6920406 | D18: =IFERROR(MAX($B$8,C18)*(1+$B$9),"") -> 2.5 | E18: =IFERROR(B18*D18,"") -> 39.116 | F18: =IFERROR(B18/(2*$B$4)+$B$5-(28+$B$7)/B18,"") -> 0.92509097 | G18: =IFERROR(MAX($B$8,F18)*(1+$B$9),"") -> 2.5 | H18: =IFERROR(B18*G18,"") -> 39.116 | I18: =IF(B18>=$B$10,"FREE-FLOW","CONGESTION") -> CONGESTION
A19: 40 | B19: =A19*0.44704 -> 17.8816 | C19: =IFERROR(B19/(2*$B$4)+$B$5-($B$6+$B$7)/B19,"") -> 2.0433855 | D19: =IFERROR(MAX($B$8,C19)*(1+$B$9),"") -> 2.5542319 | E19: =IFERROR(B19*D19,"") -> 45.673752 | F19: =IFERROR(B19/(2*$B$4)+$B$5-(28+$B$7)/B19,"") -> 1.3723046 | G19: =IFERROR(MAX($B$8,F19)*(1+$B$9),"") -> 2.5 | H19: =IFERROR(B19*G19,"") -> 44.704 | I19: =IF(B19>=$B$10,"FREE-FLOW","CONGESTION") -> CONGESTION
A20: 45 | B20: =A20*0.44704 -> 20.1168 | C20: =IFERROR(B20/(2*$B$4)+$B$5-($B$6+$B$7)/B20,"") -> 2.3663249 | D20: =IFERROR(MAX($B$8,C20)*(1+$B$9),"") -> 2.9579061 | E20: =IFERROR(B20*D20,"") -> 59.503605 | F20: =IFERROR(B20/(2*$B$4)+$B$5-(28+$B$7)/B20,"") -> 1.7698085 | G20: =IFERROR(MAX($B$8,F20)*(1+$B$9),"") -> 2.5 | H20: =IFERROR(B20*G20,"") -> 50.292 | I20: =IF(B20>=$B$10,"FREE-FLOW","CONGESTION") -> FREE-FLOW
A21: 50 | B21: =A21*0.44704 -> 22.352 | C21: =IFERROR(B21/(2*$B$4)+$B$5-($B$6+$B$7)/B21,"") -> 2.6693804 | D21: =IFERROR(MAX($B$8,C21)*(1+$B$9),"") -> 3.3367255 | E21: =IFERROR(B21*D21,"") -> 74.582488 | F21: =IFERROR(B21/(2*$B$4)+$B$5-(28+$B$7)/B21,"") -> 2.1325157 | G21: =IFERROR(MAX($B$8,F21)*(1+$B$9),"") -> 2.6656446 | H21: =IFERROR(B21*G21,"") -> 59.582488 | I21: =IF(B21>=$B$10,"FREE-FLOW","CONGESTION") -> FREE-FLOW
A22: 55 | B22: =A22*0.44704 -> 24.5872 | C22: =IFERROR(B22/(2*$B$4)+$B$5-($B$6+$B$7)/B22,"") -> 2.9579749 | D22: =IFERROR(MAX($B$8,C22)*(1+$B$9),"") -> 3.6974686 | E22: =IFERROR(B22*D22,"") -> 90.9104 | F22: =IFERROR(B22/(2*$B$4)+$B$5-(28+$B$7)/B22,"") -> 2.4699161 | G22: =IFERROR(MAX($B$8,F22)*(1+$B$9),"") -> 3.0873951 | H22: =IFERROR(B22*G22,"") -> 75.9104 | I22: =IF(B22>=$B$10,"FREE-FLOW","CONGESTION") -> FREE-FLOW
A23: 60 | B23: =A23*0.44704 -> 26.8224 | C23: =IFERROR(B23/(2*$B$4)+$B$5-($B$6+$B$7)/B23,"") -> 3.2357237 | D23: =IFERROR(MAX($B$8,C23)*(1+$B$9),"") -> 4.0446546 | E23: =IFERROR(B23*D23,"") -> 108.48734 | F23: =IFERROR(B23/(2*$B$4)+$B$5-(28+$B$7)/B23,"") -> 2.7883364 | G23: =IFERROR(MAX($B$8,F23)*(1+$B$9),"") -> 3.4854205 | H23: =IFERROR(B23*G23,"") -> 93.487343 | I23: =IF(B23>=$B$10,"FREE-FLOW","CONGESTION") -> FREE-FLOW
A24: 65 | B24: =A24*0.44704 -> 29.0576 | C24: =IFERROR(B24/(2*$B$4)+$B$5-($B$6+$B$7)/B24,"") -> 3.5051295 | D24: =IFERROR(MAX($B$8,C24)*(1+$B$9),"") -> 4.3814119 | E24: =IFERROR(B24*D24,"") -> 127.31331 | F24: =IFERROR(B24/(2*$B$4)+$B$5-(28+$B$7)/B24,"") -> 3.0921567 | G24: =IFERROR(MAX($B$8,F24)*(1+$B$9),"") -> 3.8651958 | H24: =IFERROR(B24*G24,"") -> 112.31331 | I24: =IF(B24>=$B$10,"FREE-FLOW","CONGESTION") -> FREE-FLOW
... A26: 70 | B26: =A26*0.44704 -> 31.2928 | C26: =IFERROR(B26/(2*$B$4)+$B$5-($B$6+$B$7)/B26,"") -> 3.7679803 | D26: =IFERROR(MAX($B$8,C26)*(1+$B$9),"") -> 4.7099753 | E26: =IFERROR(B26*D26,"") -> 147.38832 | F26: =IFERROR(B26/(2*$B$4)+$B$5-(28+$B$7)/B26,"") -> 3.3845055 | G26: =IFERROR(MAX($B$8,F26)*(1+$B$9),"") -> 4.2306319 | H26: =IFERROR(B26*G26,"") -> 132.38832 | I26: =IF(B26>=$B$10,"FREE-FLOW","CONGESTION") -> FREE-FLOW
A28: Reading guide: for a given SDT speed v and occluding actor length L, h_policy(v) gives the minimum time headway that, combined with an OMV hard brake (a_OMV) and worst-case g_h=0, allows SDT to stop before collision — plus a 25 % margin. Below v_thr=20 m/s the floor h_floor=2 s dominates and physical gap remains small, which is why congestion cut-in is manageable. Above v_thr the kinematic term dominates and cut-ins with a_OMV=12 m/s² and g_h=0 become unavoidable (residual SOTIF risk — OCC-014).

Sheet Sensitivity
A1: Sensitivity — h_policy at v=29 m/s, L=16 m
A3: Scenario
A4: v | B4: 29
A5: L | B5: 16
A6: g_h | B6: 0
A7: h_floor | B7: ='Actor Layer'!C21 -> 2
A8: m_safety | B8: ='Actor Layer'!C20 -> 0.25
A10: Case | B10: a_SDT (m/s²) | C10: t_total (s) | D10: h_min(v) (s) | E10: h_policy(v) (s) | F10: d_gap (m) | G10: Delta vs nominal
A11: Nominal | B11: ='Actor Layer'!C6 -> 5 | C11: ='Actor Layer'!C9 -> 1.15 | D11: =$B$4/(2*B11)+C11-($B$5+$B$6)/$B$4 -> 3.4982759 | E11: =MAX($B$7,D11)*(1+$B$8) -> 4.3728448 | F11: =$B$4*E11 -> 126.8125 | G11: =E11-E$11 -> 0
A12: −20 % brake (derate) | B12: ='Actor Layer'!C6*0.8 -> 4 | C12: ='Actor Layer'!C9 -> 1.15 | D12: =$B$4/(2*B12)+C12-($B$5+$B$6)/$B$4 -> 4.2232759 | E12: =MAX($B$7,D12)*(1+$B$8) -> 5.2790948 | F12: =$B$4*E12 -> 153.09375 | G12: =E12-E$11 -> 0.90625
A13: +20 % delay | B13: ='Actor Layer'!C6 -> 5 | C13: ='Actor Layer'!C9*1.2 -> 1.38 | D13: =$B$4/(2*B13)+C13-($B$5+$B$6)/$B$4 -> 3.7282759 | E13: =MAX($B$7,D13)*(1+$B$8) -> 4.6603448 | F13: =$B$4*E13 -> 135.15 | G13: =E13-E$11 -> 0.2875
A14: Conservative worst | B14: ='Actor Layer'!C6*0.8 -> 4 | C14: ='Actor Layer'!C9*1.2 -> 1.38 | D14: =$B$4/(2*B14)+C14-($B$5+$B$6)/$B$4 -> 4.4532759 | E14: =MAX($B$7,D14)*(1+$B$8) -> 5.5665948 | F14: =$B$4*E14 -> 161.43125 | G14: =E14-E$11 -> 1.19375
A15: Optimistic (BiL validated) | B15: ='Actor Layer'!C6*1.1 -> 5.5 | C15: ='Actor Layer'!C9*0.9 -> 1.035 | D15: =$B$4/(2*B15)+C15-($B$5+$B$6)/$B$4 -> 3.1196395 | E15: =MAX($B$7,D15)*(1+$B$8) -> 3.8995494 | F15: =$B$4*E15 -> 113.08693 | G15: =E15-E$11 -> -0.47329545

Sheet Parameter Matrix
A1: Parameter Matrix — variable ranges per OCC scenario
A3: ID | B3: v_SDT range (m/s) | C3: L range (m) | D3: a_OMV range (m/s²) | E3: g_h range (m) | F3: Visibility range (m) | G3: # variants (suggested) | H3: Notes
A4: OCC-A1 | B4: 10–30.4 | C4: 16 | D4: 5–12 | E4: 0–20 | F4: ODD | G4: 9 | H4: 3 (v) × 3 (a_OMV) — cut-out classic
A5: OCC-A2 | B5: 10–30.4 | C5: 28 | D5: 5–12 | E5: 0–20 | F5: ODD | G5: 9 | H5: Replicate A1 with double trailer
A6: OCC-A3 | B6: 15–30.4 | C6: 16 | D6: Debris=static | E6: 0–20 | F6: ODD | G6: 5 | H6: Debris size (small/medium/large) × v
A7: OCC-A4 | B7: 15–30.4 | C7: 16+16 | D7: 5–12 | E7: 0–20 | F7: ODD | G7: 6 | H7: Convoy length 2–3 — cascaded cut-out
A8: OCC-A5 | B8: 20–30.4 | C8: 16 | D8: Δv 15–25 | E8: 10–30 | F8: ODD | G8: 6 | H8: Slow-mover v_slow 5–10 m/s
A9: OCC-B1 | B9: 15–30.4 | C9: 5 | D9: 0–3 | E9: 1–5 | F9: ODD | G9: 6 | H9: Standard cut-in, well-behaved
A10: OCC-B2 | B10: 15–30.4 | C10: 5 | D10: 5 | E10: 0–3 | F10: ODD | G10: 6 | H10: Cut-in + moderate brake
A11: OCC-B3 | B11: 25–30.4 | C11: 5 | D11: 12 | E11: 0 | F11: ODD | G11: 3 | H11: Residual hard-brake, free-flow
A12: OCC-B4 | B12: 5–20 | C12: 5 | D12: 12 | E12: 0 | F12: ODD | G12: 6 | H12: Congestion hard-brake — manageable
A13: OCC-B5 | B13: 10–25 | C13: 5–16 | D13: 5–12 | E13: 0–2 | F13: ODD | G13: 6 | H13: Work-zone merge forcing cut-in
A14: OCC-C1 | B14: 20–30.4 | C14: — | D14: — | E14: — | F14: ODD | G14: 4 | H14: Crest K=100–193 (mild to severe)
A15: OCC-C2 | B15: 20–30.4 | C15: — | D15: — | E15: — | F15: ODD | G15: 4 | H15: Sag with queue depth 2–5 vehicles
... A25: OCC-E4 | B25: 10–30.4 | C25: — | D25: — | E25: — | F25: var | G25: 3 | H25: Sun elevation, tunnel portal

Sheet ODD Mapping
A1: DO-Crawl ODD subset relevant to OCC sub-activity
A3: ODD attribute | B3: DO-Crawl value | C3: Coverage via OCC scenarios | D3: Status | E3: Notes
A4: Road type | B4: Limited-access freeway (Interstate I-35) | C4: All OCC-A/B/C/D/E | D4: Covered | E4: I-35 Dallas–Laredo segment
A5: Speed band | B5: 0–68 mph (0–30.4 m/s) | C5: All, stratified | D5: Covered | E5: Parameter Matrix covers 10–68 mph
A6: Number of lanes | B6: 2–4 per direction | C6: OCC-B, OCC-D, OCC-C | D6: Covered
A7: Median | B7: Jersey barrier / grass median | C7: OCC-C3 | D7: Covered
A8: On/off ramps | B8: Standard cloverleaf + diamond | C8: OCC-C4, OCC-C5 | D8: Covered
A9: Vertical alignment | B9: Grade ≤ 4 %, crest & sag present | C9: OCC-C1, OCC-C2 | D9: Covered | E9: AASHTO K-values table used
A10: Horizontal alignment | B10: Min radius ~300 m (Texas TRC) | C10: OCC-C3 | D10: Covered
A11: Work zones | B11: Permitted (MUTCD Part 6) | C11: OCC-B5, OCC-D1 | D11: Covered
A12: Shoulder presence | B12: Paved shoulder ≥ 10 ft | C12: OCC-D2 | D12: Covered
A13: Illumination | B13: Day / dawn / dusk / night | C13: OCC-E1 | D13: Covered | E13: OCC-014 legacy requirement
A14: Visibility (weather) | B14: Dry / light rain / fog ≥ 100 m | C14: OCC-E2, OCC-E3 | D14: Covered
A15: Glare events | B15: Low-sun, tunnel entry/exit | C15: OCC-E4 | D15: Covered
A16: Other road users | B16: Passenger cars, Class 3–8 trucks, doubles | C16: OCC-A1..A5, OCC-B1..B5 | D16: Covered
A17: Pedestrians on roadway | B17: Excluded from DO-Crawl ODD | C17: — | D17: Out of ODD | E17: Not in this program
A18: VRU (motorbikes, bicycles) | B18: Motorcycles permitted; bicycles excluded | C18: Flag for TRF/SIG | D18: Partial | E18: Deferred — TRF sub-activity
A19: V2X / HD map status | B19: HD map present, V2X not required | C19: OCC-C, OCC-D implicit | D19: Covered | E19: Dependency flagged in doc

Sheet OCC Requirements
A1: OCC Requirements — sub-activity 1 (Defensive Driving in Occlusion Areas)
A3: Req ID | B3: Title | C3: Statement | D3: Rationale (SOTIF/FuSa) | E3: Verification method | F3: Evidence artifact | G3: ISO anchors
A4: OCC-001 | B4: Detect occluding actor before overtake | C4: The SDT shall detect any occluding actor (truck, trailer, barrier, bridge pier) of length ≥ L_min=4 m within the adjacent lanes at a longitudinal distance ≥ 1.5 × SSD(v) before initiating any cut-out-reveal or lane-change manoeuvre. | D4: Ensures perception leads decision for all cut-out-driven scenarios OCC-A1..A5. 1.5× factor covers sensor degradation envelope per ISO/PAS 8800. | E4: BiL (injected radar/lidar tracks) + field scenario replay | F4: BiL test report TC-OCC-001; field logs DS-1..DS-5 | G4: ISO 21448 §9.2 (perception verification); ISO/PAS 8800 §6.3
A5: OCC-002 | B5: Maintain speed-dependent time headway h(v) | C5: The SDT shall maintain an instantaneous time headway h(t) ≥ h_policy(v) where h_policy(v) = MAX(h_floor, v/(2·a_SDT) + t_total − (L+g_h)/v) × (1 + m_safety), with h_floor=2.0 s and m_safety=0.25. Below v_thr=20 m/s the floor dominates; above v_thr the kinematic term dominates. | D5: Governs every longitudinal OCC scenario (A1..A5, B2, B4). Replaces the legacy constant TORC-SYSRQ-13828 (h=4 s) which was over-conservative at low speed and under-conservative at 68 mph with 28 m doubles. | E5: Simulation sweep over Parameter Matrix; BiL; closed-course recording | F5: Excel 'Headway Envelope' sheet + BiL logs | G5: ISO 21448 §7, §10; ISO 26262-3 §6
A6: OCC-003 | B6: Anticipate cut-out reveal | C6: When an adjacent-lane occluding actor initiates a lane-change (indicated by lateral velocity ≥ 0.5 m/s or active turn-signal), the SDT shall within 0.5 s pre-build a kinematic reserve corresponding to h_policy(v) on the newly exposed longitudinal distance. | D6: Closes the loop between perception of cut-out intent and preventive braking, covering A1..A5. | E6: BiL (synthetic cut-out traces) + scenario replay | F6: BiL report TC-OCC-003 | G6: ISO 21448 §9.3 (functional insufficiencies mitigation)
A7: OCC-004 | B7: Handle convoy/cascaded cut-out | C7: If two or more occluding actors of length ≥ 4 m are tracked in echelon within h_policy(v)×v + 30 m, the SDT shall treat the convoy as a single longitudinal envelope and maintain h_policy on the envelope tail. | D7: Covers OCC-A4 — prevents undersized gap when second truck reveals after first cut-out. | E7: Simulation batch; BiL | F7: Test matrix TM-OCC-A4 | G7: ISO 21448 §7.3
A8: OCC-005 | B8: Detect cut-in maneuvers | C8: The SDT shall detect cut-in manoeuvres by adjacent-lane vehicles with TTI to lane-boundary ≤ 2 s and lateral velocity ≥ 0.3 m/s, and flag the intrusion within ≤ 0.3 s of detection threshold crossing. | D8: Prerequisite for OCC-006/007. TTI and lateral velocity thresholds aligned with UN R157 Annex 4 §3.1. | E8: BiL injection; closed-course cut-in | F8: TC-OCC-005 report | G8: UN R157 Annex 4; ISO 21448 §9.2
A9: OCC-006 | B9: Respond to aggressive cut-in (congestion regime) | C9: For v ≤ v_thr=20 m/s, on detection of a cut-in with g_h=0 and subsequent lead-vehicle deceleration ≤ a_OMV=12 m/s², the SDT shall decelerate at a_SDT=5 m/s² and avoid collision. Avoidance is verified against h_floor=2 s. | D9: Defines the 'manageable' congestion regime (OCC-B4). Consistent with congestion kinematics: the low v keeps h_floor dominant and the cut-in gap small. | E9: BiL + closed-course 20 mph / 40 mph cut-in tests | F9: TC-OCC-006 report | G9: UN R157 Annex 4; ISO 21448 §10
A10: OCC-007 | B10: Detect forced-merge cut-in at work zone | C10: Upon receiving an HD-map-annotated lane drop, work-zone, or merge-required segment, the SDT shall pre-reduce speed by Δv ≥ 3 m/s vs free-flow target and increase effective h to h_policy(v) + 0.5 s. | D10: Buffer for OCC-B5 (forced merge). MUTCD Part 6 places advance-warning signs ≥ 500 ft upstream, giving the map flag. | E10: HD-map-driven scenario replay | F10: TC-OCC-007 report | G10: ISO 21448 §9.3; MUTCD Part 6F
A11: OCC-008 | B11: Respect geometric SSD | C11: In the presence of a vertical crest (K ≤ 193) or horizontal curve, the SDT shall limit commanded speed such that SDT ≤ geometric SSD(v) − margin_geom=10 m, where SSD(v) is computed per AASHTO Green Book 2018 Table 3-1. | D11: Ensures kinematic solvability at every point of the ODD in presence of geometric occlusion (OCC-C1..C3, D3). | E11: HD-map-driven static analysis + field recording | F11: Geometric SSD audit report | G11: AASHTO Green Book 2018 §3.3; ISO 21448 §7
A12: OCC-009 | B12: Detect queued traffic in sags | C12: In sag geometries with gradient ≤ −2 %, the SDT shall pre-emptively reduce speed by ≥ 2 m/s below free-flow target unless perception confirms no queued traffic at the sag bottom within SSD(v). | D12: Covers OCC-C2 — prevents high-energy rear-end on invisible queue tails. | E12: Scenario replay; BiL | F12: TC-OCC-009 report | G12: AASHTO §3.3.2; ISO 21448 §9.3
A13: OCC-010 | B13: Maintain lateral clearance to static infrastructure | C13: The SDT shall maintain a lateral clearance ≥ 1.2 m to persistent static occlusions (barriers, piers, parked vehicles) when passing them at v > 15 m/s. | D13: Covers OCC-C3, D2, D3 — prevents secondary hazard from hidden VRU/debris. | E13: Closed-course + HIL lateral control tests | F13: TC-OCC-010 report | G13: AASHTO §10.8; ISO 21448 §7
A14: OCC-011 | B14: Respond to work-zone occlusions | C14: When HD-map indicates an active work-zone or when a persistent shoulder barrier is detected, the SDT shall adopt a defensive envelope with (a) speed ≤ posted WZ speed and (b) lane-position bias of ≥ 0.3 m away from the barrier. | D14: Covers OCC-D1 and OCC-B5 interaction with work zones. | E14: Field log replay; BiL | F14: TC-OCC-011 report | G14: MUTCD Part 6; ISO 21448 §9.3
... A17: OCC-014 | B17: Night / dawn / dusk / low-visibility envelope | C17: At illumination levels below 10 lux or visibility below 200 m, the SDT shall apply a reduced-speed curtain defined by OCC-013, and additionally increase h_policy(v) by Δh=0.5 s. | D17: Legacy requirement (referenced in E2_Scope slide 6 as OCC-014). Retained and made continuous with OCC-013. | E17: BiL + closed-course illumination test | F17: TC-OCC-014 report | G17: DO-Crawl ODD illumination band; SAE J3237 [TBV]; ISO 21448 §7

Sheet Traceability
A1: Traceability matrix — OCC requirements ↔ Scenarios ↔ ISO clauses ↔ Torc legacy
A3: OCC Req ID | B3: Covers scenarios | C3: Verifies (hazard) | D3: ISO 21448 clause | E3: Other std / reg | F3: Legacy Torc anchor (JAMA)
A4: OCC-001 | B4: OCC-A1..A5, D1..D3 | C4: Undetected occluding actor | D4: §9.2 | E4: ISO/PAS 8800 §6.3 | F4: TORC-SYSRQ-13828 (superseded on L-scope)
A5: OCC-002 | B5: OCC-A1..A5, B2, B4, C1..C5 | C5: Insufficient headway → rear-end | D5: §7, §10 | E5: UN R157 Annex 4 §3.1 | F5: TORC-SYSRQ-13828 (superseded)
A6: OCC-003 | B6: OCC-A1..A5 | C6: Late reaction to cut-out | D6: §9.3 | E6: — | F6: [TBV — new]
A7: OCC-004 | B7: OCC-A4 | C7: Cascaded undersized gap | D7: §7.3 | E7: — | F7: [TBV — new]
A8: OCC-005 | B8: OCC-B1..B5 | C8: Missed cut-in detection | D8: §9.2 | E8: UN R157 Annex 4 | F8: [TBV — correlate with existing CIN-* reqs]
A9: OCC-006 | B9: OCC-B4 | C9: Congestion cut-in hard-brake collision | D9: §10 | E9: UN R157 | F9: [TBV — new]
A10: OCC-007 | B10: OCC-B5, C4 | C10: Forced-merge under-preparation | D10: §9.3 | E10: MUTCD Part 6 | F10: [TBV — new]
A11: OCC-008 | B11: OCC-C1..C3, D3 | C11: Outrunning geometric sight distance | D11: §7 | E11: AASHTO Green Book 2018 §3.3 | F11: TORC-GEO-* [TBV]
A12: OCC-009 | B12: OCC-C2 | C12: Queue tail at sag bottom | D12: §9.3 | E12: AASHTO §3.3.2 | F12: [TBV — new]
A13: OCC-010 | B13: OCC-C3, D2, D3 | C13: Secondary hazard from side occluder | D13: §7 | E13: AASHTO §10.8 | F13: [TBV — correlate with existing GEO/LAT]
A14: OCC-011 | B14: OCC-B5, D1 | C14: Work-zone under-preparation | D14: §9.3 | E14: MUTCD 2023 Part 6 | F14: [TBV — new]
... A17: OCC-014 | B17: OCC-E1..E4 | C17: Low-light / low-visibility | D17: §7 | E17: SAE J3237 [TBV] | F17: OCC-014 (legacy, retained & refined)

Sheet TRF Scenario Catalog
A1: TRF Scenario Catalog — Sub-activity 2 (Behavior Aligns with Traffic Expectations)
A2: 17 scenarios grouped in 5 families (A Lane Discipline, B Speed, C Gap Accommodation, D Smooth Trajectory, E Social).
A3: ID | B3: Family | C3: Scenario name | D3: Context | E3: Trigger | F3: Expectation challenged | G3: Predictability hazard | H3: Governing rule/metric | I3: Temporal description (phase by phase) | J3: Governed requirement(s) | K3: Source/References
A4: TRF-A1 | B4: A — Lane Discipline | C4: Keep-right default | D4: Free-flow | E4: No overtake in progress + RL clear | F4: — (policy) | G4: LL squatting / rolling roadblock | H4: Lane occupancy policy | I4: ROAD: I-35, 2-lane highway, RL (right) and LL (left). Posted 70 mph (31.3 m/s). Moderate traffic density (LOS C). t=−60s BASELINE: SDT in RL at v=29 m/s, no lead vehicle, no overtake intent. RL traffic density such that free-flow holds. t=−30s LL TRAFFIC: sustained LL flow at v≈32 m/s (slightly above SDT). No closer vehicle in RL than 200 m. t=0 NOMINAL POLICY: SDT remains in RL (TRF-001 keep-right default). Lateral position centered ±0.2 m (TRF-005). OUTCOME: SDT uses LL only for overtake events, aligning with Texas TRC §545.051 and FHWA BC §Lane-Discipline. No unexpected LL occupancy, no 'rolling roadblock' appearance. | J4: TRF-001, 005 | K4: Texas TRC §545.051; FHWA BC §Lane-Discipline
A5: TRF-A2 | B5: A — Lane Discipline | C5: Return-to-right after pass | D5: Free-flow | E5: Overtake completes (SDT clears OMV by ≥1.5 s) | F5: Slow OMV in RL | G5: LL-squatting after overtake | H5: t_return_RL ≤ 15 s | I5: ROAD: I-35, 2-lane. SDT overtakes a slower OMV. t=−10s OVERTAKE INIT: SDT at v=29 m/s in RL behind OMV at v=24 m/s, d=+60 m. Left turn signal activates t=−10s (TRF-008 signal 3 s lead for LC). t=−7s→−4s LC LEFT: SDT crosses to LL, maneuver duration 3 s. t=−4s→+0s PASSING: SDT parallel to OMV, clears OMV front by ≥ 1.5 s headway equivalent (≈44 m). t=+0s→+3s RETURN-TO-RL: Right turn signal at t=0, LC right at t=+3s to +6s. TOTAL time in LL: 13 s (well under t_return_RL=15 s threshold for TRF-002). OUTCOME: overtake completed with prompt return to RL; no LL-squatting. | J5: TRF-002, 008 | K5: Texas TRC §545.051; UN R157 §5.6.2
A6: TRF-A3 | B6: A — Lane Discipline | C6: No rolling roadblock | D6: Free-flow | E6: SDT in LL at v<posted while RL clear > 5 s | F6: — (policy) | G6: Roadblock appearance in LL | H6: t_LL_clear_max ≤ 30 s | I6: ROAD: I-35, 2-lane, RL clear for >200 m, LL available. t=−30s SDT in LL at v=28 m/s (below posted 70 mph = 31.3), no overtake in progress. t=−30s→t=0 RL MONITOR: SDT perception confirms RL clear and v_sustainable ≥ LL speed. DECISION: TRF-003 forbids holding LL when (i) RL is clear > 5 s and (ii) no active overtake. t=0 TRIGGER: SDT initiates LC to RL at t=0, completes t=+5s. OUTCOME: 'rolling roadblock' avoided. SDT never occupies LL more than t_LL_clear_max = 30 s when RL clear. | J6: TRF-003 | K6: Texas TRC §545.051; FHWA BC
A7: TRF-A4 | B7: A — Lane Discipline | C7: Yield to faster vehicle in LL | D7: Free-flow | E7: Faster OMV approaches SDT from behind in LL | F7: Following vehicle | G7: Impeding faster traffic | H7: Vacate LL ASAP | I7: ROAD: I-35, 2-lane. SDT in LL completing an overtake, faster vehicle OMV2 approaching from behind in LL. t=−8s SDT at v=29 m/s in LL (overtaking slow OMV1 at v=24 in RL). OMV2 in LL at d=−100 m (behind), v=33 m/s, Δv closing. t=−5s DETECTION: SDT perception flags OMV2 closing; TTC at current d ≈ 25 s (non-critical). t=0 RULE: TRF-004 requires SDT to complete LC back to RL as soon as gap to OMV1 allows, not to force OMV2 to brake. t=0→+5s LC RIGHT: SDT returns to RL, signal 3 s lead. OUTCOME: OMV2 passes freely in LL, no constraint imposed. Texas TRC §545.053 (overtake on left) respected. | J7: TRF-004 | K7: Texas TRC §545.053
A8: TRF-A5 | B8: A — Lane Discipline | C8: Full-lane placement | D8: Either | E8: Nominal cruise in any lane | F8: — (policy) | G8: Lateral drift, lane ambiguity | H8: |e_lat| ≤ 0.3 m | I8: ROAD: I-35, 2-lane, straight, level, no vehicles within 100 m. t=0 CRUISE: SDT in RL at v=29 m/s. METRIC: lateral deviation from lane centerline measured by controller: target 0 m, cap |e_lat|=0.3 m (TRF-005 lane-keep). INTEGRATION WINDOW: 10 s sliding. 95th percentile |e_lat| ≤ 0.2 m. OUTCOME: SDT lane position predictable; observers can rely on centered positioning, no 'drifting' artifacts. | J8: TRF-005, 014 | K8: FMCSA 49 CFR §392.14; ISO 11270
A9: TRF-B1 | B9: B — Speed Management | C9: Posted speed compliance | D9: Free-flow | E9: Posted limit known, no gradient constraint | F9: Signage | G9: Under-speed or over-speed | H9: v ∈ [posted−5, posted+3] mph | I9: ROAD: I-35 posted 70 mph (31.3 m/s), light traffic. t=0 CRUISE: SDT at v=29 m/s in RL (−5 mph from posted). Policy band: [posted−5, posted+3] mph ≈ [29.1, 32.6] m/s. DECISION: SDT ramps +2 m/s² to reach v=30 m/s within 1 s → inside band. OUTCOME: Speed compliance achieved. Not 'rolling roadblock' (TRF-006). Not over-limit (legal). No abrupt change (|j_long| ≤ 2 m/s³ per TRF-013). | J9: TRF-006 | K9: Texas TRC §545.352
A10: TRF-B2 | B10: B — Speed Management | C10: Flow-match in free-flow | D10: Free-flow | E10: Traffic flows above posted at 85th percentile | F10: Prevailing flow | G10: Anomaly vs. flow | H10: dv_flow ≤ 5 m/s | I10: ROAD: I-35 posted 70 mph, heavy traffic at 85th percentile flow speed v_flow=34 m/s (≈76 mph, common I-35 Texas). t=0 SDT in RL at v=30 m/s (at posted +0). OBSERVED: flow at 34 m/s; Δv=v_flow−v_SDT=4 m/s < dv_flow=5 m/s threshold → SDT holds posted (TRF-007). ALTERNATIVE: if Δv > 5 m/s and SDT becomes traffic anomaly, HMI can suggest driver take-over, but ADS cannot exceed posted speed +3 mph legally. OUTCOME: compliance with Texas TRC §545.352 (max speed) preserved; flow discontinuity minimized within legal envelope. | J10: TRF-007 | K10: HCM 2016 Ch.12; AAA Foundation
A11: TRF-B3 | B11: B — Speed Management | C11: Smooth approach to queue | D11: Free-flow | E11: Queue tail detected at d ≥ 200 m | F11: Stopped/slow traffic | G11: Abrupt hard-brake propagation | H11: a_queue ≤ 1.5 m/s² | I11: ROAD: I-35, queue forming ahead (construction downstream). SDT at v=29 m/s, queue tail visible at d=+300 m, v_tail=0. t=−10s DETECTION: stationary queue detected. t=−10s→t=0 SMOOTH DECELERATION: SDT decels at a_queue_target=1.5 m/s² (TRF-009), v ramps 29→14 m/s over ~10 s, distance covered ~215 m. t=0 JOIN QUEUE: SDT approaches tail at Δv≈0, h_floor=2 s applied. OUTCOME: smooth join, no hard brake visible to traffic behind. |j_long| bounded to 2 m/s³. CONTRAST: the unwanted behavior is last-second hard brake at 5 m/s² — this would propagate rear-end risk upstream. | J11: TRF-009, 013 | K11: UN R157 §5.6.2; NHTSA BC
A12: TRF-B4 | B12: B — Speed Management | C12: Minimum-speed compliance | D12: Either | E12: Gradient or loading forces v below flow | F12: SDT engine limit | G12: Illegally slow | H12: v ≥ 17.9 m/s (40 mph) | I12: ROAD: I-35, 2-lane, long uphill grade +5%. SDT is loaded GCVW 80 000 lb, engine-limited speed ~45 mph on grade. t=0 SDT v=20 m/s, posted 70 mph. Flow in RL at 22 m/s (also slowed by grade). RULE CHECK: TRF-008 = Texas TRC §545.351 (minimum 40 mph on Interstate). SDT at v=20 m/s = 44.7 mph → complies. EDGE CASE: if SDT v drops below 17.9 m/s (40 mph) due to grade, hazards activate (handled by SIG — out of TRF scope). OUTCOME: minimum-speed compliance preserved; use of RL keeps faster vehicles free to overtake. | J12: TRF-008 | K12: Texas TRC §545.351
A13: TRF-C1 | B13: C — Gap Accommodation | C13: On-ramp merger accommodation | D13: Either | E13: V_merge detected with merge intent | F13: Merging vehicle | G13: Forcing V_merge to stop | H13: t_gap ≥ 1.5 s offered | I13: ROAD: I-35 with on-ramp merge, 250-m acceleration lane. SDT in RL at v=29 m/s. t=−10s DETECTION: V_merge in acceleration lane at d=+80 m lateral offset 3 m, v=22 m/s (ramp speed). t=−6s INTENT: V_merge signal on, lateral motion begin. TRF-010 mandates SDT offers gap ≥ t_gap_merger=1.5 s (≈44 m at v=29). t=−4s→+0s GAP CREATION: SDT applies |a|≤1.5 m/s² brake, reduces v to 26 m/s to create 1.5 s gap. t=0 MERGE: V_merge enters RL ahead of SDT, h observed ≥ 1.5 s. OUTCOME: cooperative merge; V_merge not forced to stop in acceleration lane. | J13: TRF-010 | K13: AAA Foundation NDS; FHWA BC
A14: TRF-C2 | B14: C — Gap Accommodation | C14: Zipper merge participation | D14: Congestion | E14: Work-zone LL→RL late-merge taper | F14: Alternating merge | G14: Zipper lockout | H14: t_gap_zipper ≥ 1.0 s | I14: ROAD: I-35 work-zone, LL closed, late-merge zipper approach. Flow in RL backed up. t=−20s SDT in RL at v=15 m/s in slow queue. V_zipper in LL next to SDT, v=15 m/s, intending to merge into RL. RULE: TRF-011 (zipper merge) — SDT alternates with LL when they reach the merge taper per MUTCD. t=0 TAPER: SDT opens gap t_gap_zipper=1.0 s (≈15 m) to let V_zipper in. OUTCOME: throughput maintained per MUTCD Part 6C late-merge guidance; no road rage trigger. | J14: TRF-011 | K14: MUTCD 2023 Part 6C; FHWA late-merge
... A20: TRF-E2 | B20: E — Social/Regulatory | C20: Appropriate following distance | D20: Free-flow | E20: SDT follows OMV in nominal cruise | F20: Lead vehicle | G20: Tailgating or inviting cut-ins | H20: h ∈ [2.0, h_policy] s | I20: ROAD: I-35 RL. Following lead OMV at v=29 m/s. RULE: h_policy(29,L=16)=4.37 s for OCC compliance. SOCIAL TENSION: 4.37 s gap is ≥ 126 m, invites cut-ins (see OCC-B3 residual). TRF MITIGATION: during REGIME=free-flow with low LL traffic, SDT can adopt h_policy_soc slightly below OCC envelope only if perception horizon ≥ SSD(v); otherwise OCC wins. OUTCOME: balanced following; not tailgating (TRF-015 forbid h < h_floor=2.0 s) and not inviting cut-ins beyond design envelope. | J20: TRF-015 | K20: Texas TRC §545.062; FHWA BC

Sheet TRF Requirements
A1: TRF Requirements — Traffic Expectation Behaviors
A3: Req ID | B3: Behavior family | C3: Requirement statement | D3: Rationale (SOTIF/UX) | E3: Metric / threshold | F3: Scenarios governed | G3: Verification method | H3: Source / standard
A4: TRF-001 | B4: A Lane Discipline | C4: The SDT SHALL occupy the rightmost lane available (RL) when no overtake is in progress and RL is free of hazards. | D4: Conforms with Texas TRC §545.051 'keep-right' rule and FHWA BC §Lane-Discipline. Prevents LL-squatting. | E4: LL occupancy time when RL clear ≤ 0 s outside overtake + LC window. | F4: TRF-A1, A3 | G4: Closed-course + simulation; JAMA test TORC-LD-001 [TBV] | H4: Texas TRC §545.051; FHWA BC (2018)
A5: TRF-002 | B5: A Lane Discipline | C5: The SDT SHALL return to RL within t_return_RL = 15 s after clearing the overtaken vehicle by ≥ 1.5 s headway. | D5: Balances completion safety and courtesy; avoids LL-occupancy beyond the legal pretext of 'overtaking'. | E5: time_in_LL − time_overtake_complete ≤ 15 s. | F5: TRF-A2, C4 | G5: Simulation replay; naturalistic-ish testing on DO-Crawl stretch | H5: Texas TRC §545.051; internal policy [TBV]
A6: TRF-003 | B6: A Lane Discipline | C6: The SDT SHALL NOT occupy LL for more than t_LL_clear_max = 30 s when RL is free and no overtake is active. | D6: Caps worst-case 'rolling roadblock' perception; internal courtesy rule. | E6: LL continuous occupancy ≤ 30 s when RL available. | F6: TRF-A3 | G6: Simulation; closed-course replay | H6: Internal Torc policy [TBV]
A7: TRF-004 | B7: A Lane Discipline | C7: When SDT is in LL and a faster OMV approaches from behind at closing Δv ≥ 2 m/s, SDT SHALL vacate LL as soon as RL gap permits. | D7: Texas TRC §545.053 — overtake on left; implies left-lane is reserved for passing. | E7: LC-right initiated within 5 s of closing-OMV detection if RL gap ≥ 1.5 s. | F7: TRF-A4 | G7: Simulation + closed-course | H7: Texas TRC §545.053
A8: TRF-005 | B8: A Lane Discipline | C8: The SDT SHALL maintain its lateral position within ±0.3 m of lane centerline under nominal conditions. | D8: Lane-keep predictability for surrounding drivers; ISO 11270 LKA standard. | E8: 95th percentile |e_lat| ≤ 0.3 m over 30 s window. | F8: TRF-A5, D2 | G8: Closed-course with centimeter-grade reference; logged control data | H8: ISO 11270:2014; FMCSA §392.14
A9: TRF-006 | B9: B Speed Management | C9: The SDT SHALL target v ∈ [v_posted − 5 mph, v_posted + 3 mph] on limited-access highway, subject to flow-match rule (TRF-007). | D9: Legal compliance (Texas TRC §545.352) + anti-rolling-roadblock. | E9: Steady-state v within [posted−5, posted+3] mph for ≥ 95% of cruise window. | F9: TRF-B1 | G9: Naturalistic logs; simulation | H9: Texas TRC §545.352
A10: TRF-007 | B10: B Speed Management | C10: When prevailing flow exceeds v_posted, the SDT SHALL remain at v_posted + upper tolerance; it SHALL NOT exceed legal max to match flow. | D10: Legal priority over flow-match; Δv to flow is tolerated up to dv_flow = 5 m/s before HMI suggests driver take-over. | E10: SDT v ≤ v_posted + 3 mph at all times; Δv_flow ≤ 5 m/s reported OK. | F10: TRF-B2 | G10: Naturalistic logs | H10: Texas TRC §545.352; HCM 2016
A11: TRF-008 | B11: B Speed Management | C11: The SDT SHALL maintain v ≥ 17.9 m/s (40 mph) on Interstate absent grade limits, breakdown, or law-enforcement direction. | D11: Texas TRC §545.351 minimum-speed rule. Engine-limited climb triggers hazard lights (SIG deliverable). | E11: v ≥ 17.9 m/s or hazards + deceleration-lane usage active. | F11: TRF-B4 | G11: Simulation grade profile; tracked via HMI state | H11: Texas TRC §545.351
