Workbook

Sheet Lisez-moi
A1: Catalogue des scénarios abstraits et lien Behavior × Catalogue (v3, PROPOSED)
A2: SERYTI pour Torc Robotics, DO-Crawl I-35 South, 7 octobre 2026. Même contenu que l'outil Scenario Studio.
A4: Ce que c'est | B4: 121 scénarios abstraits (situations uniques) et leurs liens vers les 21 behaviors de la Behavior Table Torc. Un abstract peut vérifier plusieurs behaviors (lien n:m) : 258 liens au total.
A5: D'où viennent les abstracts | B5: Écrits par SERYTI. Ils ne viennent pas de la bibliothèque Foretellix (sous licence) : seule la structure (acteurs, phases, paramètres, coverage) suit le format Foretellix. Sources : Miro Torc (Concrete A/B), HAZOP/HIRE v2, catalogue TC-CRAWL V3, typologie NHTSA pré-crash (DOT HS 810 767), définitions Jama des behaviors (export du 26/03/2026).
A6: Foretellix | B6: La bibliothèque publique Foretellix / SAFE « Highway and ADAS Traffic Scenario Library » (VMAD-SG1-11-06, novembre 2020, 13 scénarios fonctionnels) a été croisée avec le catalogue : 9 abstracts ont été ajoutés pour les situations applicables qui manquaient (convoi lent à côté, lane hugger, file arrêtée à côté, courbe avec voisin, leader qui sort, convoi qui s'insère, entrecroisement à l'insertion, double cut-in, cut-out simple). Onglet « Couverture Foretellix ». Le catalogue Torc réel est la « L4 Highway Trucking V-Suite » de Foretellix, non publique : à demander (scenario index and coverage model).
A7: Justification HIRE | B7: Chaque lien abstract → behavior est justifié par des lignes du HIRE v2 (2026_SDT_HIRE_from_HAZOP_v2, 1 156 HARA) et rattaché aux HFS (Hazardous_Functional_Scenarios_V1). Règle : « justifié » quand le HIRE du behavior relie une commande sollicitée par la scène (décélération, braquage, accélération, clignotant, feux) au hazard pour lequel l'abstract a été écrit ; « justifié indirectement » quand c'est un autre hazard exposé par la scène, ou quand l'abstract n'est pas encore générable (hazard seul). Onglets « Justification HIRE » (une ligne par lien) et « Trous HIRE » (combinaisons du HIRE sans abstract).
A8: Ce que l'analyse a changé | B8: 5 liens ajoutés parce que le HIRE contient la condition ODD pour ce behavior et qu'aucun abstract ne la couvrait (OBJ-04, LC-OOD-04 et OBJ-06 pour Cruise ; RD-13 et OBJ-02 pour Controlled Stop on Shoulder), et 1 abstract créé : RMP-14 (bretelle d'accès en courbe et en pente, H5 de On-Ramp Merge).
A9: Ce qui manque | B9: Le catalogue de Matthieu (environ 104 abstracts, colonne A famille, colonne B abstract, nombre à confirmer) n'est pas dans le dossier. La colonne « Équivalent catalogue Matthieu » de l'onglet Catalogue est prévue pour faire le rapprochement.
A10: Intention du SDT | B10: Chaque behavior impose une intention au SDT pour la génération : K rester dans la voie, L changement de voie, M se décaler, S arrêt sur l'accotement, I arrêt en voie, E évitement latéral. L'intention est observée sur l'ADS, jamais scriptée dans l'OSC.
A11: Génération | B11: Les abstracts autoroute et les abstracts urbains en voie sont générables dans l'outil (acteurs A à O). Les intersections, la marche arrière, le contresens et la cour du hub ne le sont pas encore (jalon 2) : ils sont dans le catalogue et dans la matrice, sans génération.
A12: Exigences Jama | B12: Liens proposés vers les exigences de l'export « Driver Out 2026 SDT Requirements » (définitions des behaviors, Lane Change, Stay in Lane, OMV, vitesses) et vers TORC-SYSRQ-15232 et TORC-FSR-3752 (instantané local du repo Scenario Studio). À relire.
A13: Onglets | B13: Catalogue · Matrice Behavior × Abstract · Justification HIRE · Trous HIRE · Behaviors · Couverture NHTSA · Couverture Foretellix · Exigences Jama.
A14: Statut | B14: PROPOSED. Aucun lien n'est validé par Torc.

Sheet Catalogue
A1: Catalogue : une ligne par scénario abstrait
A2: Concrets = combinaisons générées par l'outil avec les valeurs par défaut, sommées sur les behaviors liés.
A4: ID | B4: Famille | C4: Titre | D4: Description | E4: Use cases | F4: Behaviors liés | G4: Nb behaviors | H4: Acteurs (slot, présence, types, manœuvres) | I4: Générable | J4: Combinaisons | K4: Concrets retenus | L4: Concrets exclus | M4: NHTSA pré-crash | N4: Hazards | O4: Triggering conditions | P4: Exigences Jama | Q4: Dépend de la perception | R4: Source | S4: Statut | T4: Équivalent catalogue Matthieu | U4: Foretellix SAFE (VMAD 2020)
A5: LV-01 | B5: LV | C5: Route libre, aucun leader | D5: Le SDT roule seul dans sa voie : comportement par défaut, vitesse et centrage. | E5: Highway | F5: HW-CRU, URB-CRU | G5: =IF(F5="",0,LEN(F5)-LEN(SUBSTITUTE(F5,",",""))+1) | H5: aucun (SDT seul) | I5: oui | J5: 24 | K5: 20 | L5: 4 | N5: H1, H5 | P5: TORC-SYSRQ-10155, TORC-SYSRQ-10154, TORC-SYSRQ-10161, TORC-SYSRQ-10167, TORC-SYSRQ-14118 | Q5: non | R5: SERYTI catalogue v1 (PROPOSED) | S5: PROPOSED
A6: LV-02 | B6: LV | C6: Leader plus lent à vitesse constante | D6: Le SDT rattrape un véhicule plus lent dans sa voie et passe en suivi. | E6: Highway | F6: HW-CRU, HW-FOL, URB-FOL | G6: =IF(F6="",0,LEN(F6)-LEN(SUBSTITUTE(F6,",",""))+1) | H6: A (obligatoire) : car, tractor_trailer | I6: oui | J6: 216 | K6: 216 | L6: 0 | M6: #25 Lead vehicle moving at lower constant speed | N6: H2 | P6: TORC-SYSRQ-14122, TORC-SYSRQ-14066 | Q6: non | R6: SERYTI catalogue v1 (PROPOSED) | S6: PROPOSED | U6: §11 Lead vehicle (couvert)
A7: LV-03 | B7: LV | C7: Leader qui décélère modérément | D7: Le leader ralentit sans urgence ; le SDT ajuste sa distance. | E7: Highway | F7: HW-FOL, URB-FOL | G7: =IF(F7="",0,LEN(F7)-LEN(SUBSTITUTE(F7,",",""))+1) | H7: A (obligatoire) : car, tractor_trailer · brake | I7: oui | J7: 128 | K7: 128 | L7: 0 | M7: #26 Lead vehicle decelerating | N7: H2 | P7: TORC-SYSRQ-14122, TORC-SYSRQ-14066 | Q7: non | R7: SERYTI catalogue v1 (PROPOSED) | S7: PROPOSED | U7: §11 Lead vehicle (couvert)
A8: LV-04 | B8: LV | C8: Leader qui freine fort | D8: Le leader freine brutalement ; le SDT doit éviter la collision avant. | E8: Highway | F8: HW-FOL, HW-ESL, HW-ELM, URB-FOL | G8: =IF(F8="",0,LEN(F8)-LEN(SUBSTITUTE(F8,",",""))+1) | H8: A (obligatoire) : car, tractor_trailer · brake | I8: oui | J8: 192 | K8: 128 | L8: 64 | M8: #26 Lead vehicle decelerating | N8: H2 | O8: TC-CRAWL-185 | P8: TORC-SYSRQ-14066 | Q8: non | R8: SERYTI catalogue v1 (PROPOSED) | S8: PROPOSED | U8: §11 Lead vehicle (couvert)
A9: LV-05 | B9: LV | C9: Leader arrêté (fin de bouchon, véhicule arrêté) | D9: Un véhicule est arrêté dans la voie du SDT. | E9: Highway | F9: HW-CRU, HW-FOL, HW-ESL, HW-ELM, HW-LC, URB-FOL | G9: =IF(F9="",0,LEN(F9)-LEN(SUBSTITUTE(F9,",",""))+1) | H9: A (obligatoire) : car, tractor_trailer | I9: oui | J9: 144 | K9: 144 | L9: 0 | M9: #27 Lead vehicle stopped | N9: H2 | O9: TC-CRAWL-182 | P9: TORC-SYSRQ-14066, TORC-SYSRQ-14123 | Q9: non | R9: SERYTI catalogue v1 (PROPOSED) | S9: PROPOSED | U9: §10 Stopped vehicles (couvert)
A10: LV-06 | B10: LV | C10: Leader qui accélère et s'éloigne | D10: Le leader repart ; le SDT reprend sa vitesse sans à-coup. | E10: Highway | F10: HW-FOL, URB-FOL | G10: =IF(F10="",0,LEN(F10)-LEN(SUBSTITUTE(F10,",",""))+1) | H10: A (obligatoire) : car · accelerate | I10: oui | J10: 64 | K10: 64 | L10: 0 | M10: #24 Lead vehicle accelerating | N10: H2, H3 | P10: TORC-SYSRQ-14122 | Q10: non | R10: SERYTI catalogue v1 (PROPOSED) | S10: PROPOSED | U10: §11 Lead vehicle (couvert)
A11: LV-07 | B11: LV | C11: Accordéon (stop-and-go) | D11: Trafic dense qui ralentit et repart. | E11: Highway | F11: HW-FOL, URB-FOL | G11: =IF(F11="",0,LEN(F11)-LEN(SUBSTITUTE(F11,",",""))+1) | H11: A (obligatoire) : car, tractor_trailer · brake C (optionnel) : car | I11: oui | J11: 1024 | K11: 1024 | L11: 0 | M11: #26 Lead vehicle decelerating | N11: H2, H3 | O11: TC-CRAWL-173 | Q11: non | R11: SERYTI catalogue v1 (PROPOSED) | S11: PROPOSED | U11: §10 Stopped vehicles (partiel), §11 Lead vehicle (couvert)
A12: LV-08 | B12: LV | C12: Leader au comportement erratique | D12: Le leader freine et accélère de façon imprévisible. | E12: Highway | F12: HW-FOL | G12: =IF(F12="",0,LEN(F12)-LEN(SUBSTITUTE(F12,",",""))+1) | H12: A (obligatoire) : car, pickup · brake | I12: oui | J12: 128 | K12: 128 | L12: 0 | M12: #26 Lead vehicle decelerating | N12: H2 | O12: TC-CRAWL-181, TC-CRAWL-175 | Q12: non | R12: SERYTI catalogue v1 (PROPOSED) | S12: PROPOSED | U12: §11 Lead vehicle (couvert)
A13: LV-09 | B13: LV | C13: Moto en leader | D13: Petit véhicule devant, difficile à suivre et à détecter. | E13: Highway | F13: HW-CRU, HW-FOL | G13: =IF(F13="",0,LEN(F13)-LEN(SUBSTITUTE(F13,",",""))+1) | H13: A (obligatoire) : motorcycle | I13: oui | J13: 32 | K13: 32 | L13: 0 | M13: #25 Lead vehicle moving at lower constant speed | N13: H2 | O13: TC-CRAWL-200 | Q13: oui | R13: SERYTI catalogue v1 (PROPOSED) | S13: PROPOSED
A14: LV-10 | B14: LV | C14: Leader camion qui masque la vue | D14: Un semi devant cache un véhicule arrêté plus loin. | E14: Highway | F14: HW-FOL, HW-ESL | G14: =IF(F14="",0,LEN(F14)-LEN(SUBSTITUTE(F14,",",""))+1) | H14: A (obligatoire) : tractor_trailer O (optionnel) : stopped_vehicle | I14: oui | J14: 32 | K14: 32 | L14: 0 | M14: #27 Lead vehicle stopped | N14: H2 | O14: TC-CRAWL-186 | Q14: oui | R14: SERYTI catalogue v1 (PROPOSED) | S14: PROPOSED
A15: LV-11 | B15: LV | C15: Le leader change de voie et libère la voie (cut-out) | D15: Le véhicule suivi quitte la voie du SDT sans obstacle derrière : le SDT doit reprendre sa vitesse sans à-coup (Foretellix « cut out »). | E15: Highway | F15: HW-CRU, HW-FOL | G15: =IF(F15="",0,LEN(F15)-LEN(SUBSTITUTE(F15,",",""))+1) | H15: A (obligatoire) : car, pickup, tractor_trailer · cut_out | I15: oui | J15: 432 | K15: 432 | L15: 0 | N15: H2 | P15: TORC-SYSRQ-14122, TORC-SYSRQ-10167 | Q15: non | R15: SERYTI catalogue v1 (PROPOSED) | S15: PROPOSED | U15: §5 Cut out (couvert)
A16: CI-01 | B16: CI | C16: Cut-in depuis la gauche, gap suffisant | D16: Un véhicule de la voie de gauche se rabat devant le SDT avec un écart correct. | E16: Highway | F16: HW-CRU, HW-FOL, URB-FOL | G16: =IF(F16="",0,LEN(F16)-LEN(SUBSTITUTE(F16,",",""))+1) | H16: B (obligatoire) : car, pickup · cut_in | I16: oui | J16: 288 | K16: 288 | L16: 0 | M16: #19 Vehicle(s) changing lanes, same direction | N16: H2 | O16: TC-CRAWL-171 | P16: TORC-SYSRQ-14066, TORC-SYSRQ-14122 | Q16: non | R16: SERYTI catalogue v1 (PROPOSED) | S16: PROPOSED | U16: §2 Cut in (couvert)
A17: CI-02 | B17: CI | C17: Cut-in serré depuis la gauche | D17: Le véhicule se rabat très près devant le SDT. | E17: Highway | F17: HW-CRU, HW-FOL, HW-ESL | G17: =IF(F17="",0,LEN(F17)-LEN(SUBSTITUTE(F17,",",""))+1) | H17: B (obligatoire) : car, pickup · cut_in | I17: oui | J17: 192 | K17: 192 | L17: 0 | M17: #19 Vehicle(s) changing lanes, same direction | N17: H2 | O17: TC-CRAWL-175 | P17: TORC-SYSRQ-14066 | Q17: non | R17: SERYTI catalogue v1 (PROPOSED) | S17: PROPOSED | U17: §2 Cut in (couvert)
A18: CI-03 | B18: CI | C18: Cut-in depuis la droite | D18: Un véhicule de la voie de droite se rabat devant le SDT (SDT en voie du milieu ou de gauche). | E18: Highway | F18: HW-CRU, HW-FOL | G18: =IF(F18="",0,LEN(F18)-LEN(SUBSTITUTE(F18,",",""))+1) | H18: G (obligatoire) : car, pickup · cut_in | I18: oui | J18: 128 | K18: 128 | L18: 0 | M18: #19 Vehicle(s) changing lanes, same direction | N18: H2 | P18: TORC-SYSRQ-14066 | Q18: non | R18: SERYTI catalogue v1 (PROPOSED) | S18: PROPOSED | U18: §2 Cut in (couvert)
A19: CI-04 | B19: CI | C19: Cut-in d'un véhicule plus lent | D19: Le véhicule qui se rabat roule moins vite que le SDT. | E19: Highway | F19: HW-CRU, HW-FOL | G19: =IF(F19="",0,LEN(F19)-LEN(SUBSTITUTE(F19,",",""))+1) | H19: B (obligatoire) : car, pickup · cut_in | I19: oui | J19: 64 | K19: 64 | L19: 0 | M19: #19 Vehicle(s) changing lanes, same direction, #25 Lead vehicle moving at lower constant speed | N19: H2 | Q19: non | R19: SERYTI catalogue v1 (PROPOSED) | S19: PROPOSED | U19: §2 Cut in (couvert)
A20: CI-05 | B20: CI | C20: Cut-in d'un semi-remorque | D20: Un ensemble long se rabat devant le SDT. | E20: Highway | F20: HW-CRU, HW-FOL | G20: =IF(F20="",0,LEN(F20)-LEN(SUBSTITUTE(F20,",",""))+1) | H20: B (obligatoire) : tractor_trailer · cut_in | I20: oui | J20: 64 | K20: 64 | L20: 0 | M20: #19 Vehicle(s) changing lanes, same direction | N20: H2 | O20: TC-CRAWL-187 | Q20: non | R20: SERYTI catalogue v1 (PROPOSED) | S20: PROPOSED | U20: §2 Cut in (couvert)
A21: CI-06 | B21: CI | C21: Insertion depuis la bretelle devant le SDT | D21: Un véhicule de la voie d'accélération s'insère dans la voie de droite où roule le SDT. | E21: Highway | F21: HW-CRU, HW-FOL | G21: =IF(F21="",0,LEN(F21)-LEN(SUBSTITUTE(F21,",",""))+1) | H21: G (obligatoire) : car, pickup, tractor_trailer · cut_in | I21: oui | J21: 288 | K21: 288 | L21: 0 | M21: #19 Vehicle(s) changing lanes, same direction | N21: H1, H2 | O21: TC-CRAWL-052, TC-CRAWL-265 | Q21: non | R21: SERYTI catalogue v1 (PROPOSED) | S21: PROPOSED | U21: §4.1.3 Cars merge at highway entry (partiel)
A22: CI-07 | B22: CI | C22: Brake-check après un rabattement | D22: Un véhicule qui vient de se rabattre freine brutalement devant le SDT. | E22: Highway | F22: HW-FOL, HW-ESL | G22: =IF(F22="",0,LEN(F22)-LEN(SUBSTITUTE(F22,",",""))+1) | H22: A (obligatoire) : car · brake | I22: oui | J22: 32 | K22: 32 | L22: 0 | M22: #26 Lead vehicle decelerating | N22: H2 | O22: TC-CRAWL-175 | Q22: non | R22: SERYTI catalogue v1 (PROPOSED) | S22: PROPOSED
A23: CI-08 | B23: CI | C23: Deux véhicules se rabattent l'un après l'autre | D23: Deux véhicules de la voie de gauche se rabattent successivement devant le SDT (variante convoi du cut-in Foretellix). | E23: Highway | F23: HW-CRU, HW-FOL | G23: =IF(F23="",0,LEN(F23)-LEN(SUBSTITUTE(F23,",",""))+1) | H23: B (obligatoire) : car, pickup · cut_in | I23: oui | J23: 256 | K23: 256 | L23: 0 | M23: #19 Vehicle(s) changing lanes, same direction | N23: H2 | P23: TORC-SYSRQ-14066, TORC-SYSRQ-14122 | Q23: non | R23: SERYTI catalogue v1 (PROPOSED) | S23: PROPOSED | U23: §2 Cut in (couvert), §5 Cut out (partiel)
A24: ADJ-01 | B24: ADJ | C24: Véhicule adjacent qui dérive vers le SDT | D24: Un véhicule le long du SDT sort de sa voie vers lui. | E24: Highway | F24: HW-CRU, HW-FOL, HW-ELM | G24: =IF(F24="",0,LEN(F24)-LEN(SUBSTITUTE(F24,",",""))+1) | H24: D (obligatoire) : car, pickup · drift | I24: oui | J24: 288 | K24: 288 | L24: 0 | M24: #20 Vehicle(s) drifting, same direction | N24: H1 | O24: TC-CRAWL-171 | P24: TORC-SYSRQ-14128, TORC-SYSRQ-10180, TORC-SYSRQ-14065 | Q24: non | R24: SERYTI catalogue v1 (PROPOSED) | S24: PROPOSED | U24: §8 Lane hugger (partiel)
A25: ADJ-02 | B25: ADJ | C25: Semi adjacent dont la remorque louvoie | D25: La remorque d'un camion voisin oscille vers la voie du SDT. | E25: Highway | F25: HW-CRU, HW-FOL | G25: =IF(F25="",0,LEN(F25)-LEN(SUBSTITUTE(F25,",",""))+1) | H25: D (obligatoire) : tractor_trailer · drift | I25: oui | J25: 48 | K25: 48 | L25: 0 | M25: #20 Vehicle(s) drifting, same direction | N25: H1 | O25: TC-CRAWL-192 | P25: TORC-SYSRQ-14128 | Q25: non | R25: SERYTI catalogue v1 (PROPOSED) | S25: PROPOSED
A26: ADJ-03 | B26: ADJ | C26: Moto qui remonte les files | D26: Une moto rapide passe entre les voies le long du SDT. | E26: Highway | F26: HW-CRU, HW-FOL | G26: =IF(F26="",0,LEN(F26)-LEN(SUBSTITUTE(F26,",",""))+1) | H26: D (obligatoire) : motorcycle | I26: oui | J26: 32 | K26: 32 | L26: 0 | M26: #20 Vehicle(s) drifting, same direction | N26: H1 | O26: TC-CRAWL-200, TC-CRAWL-201 | P26: TORC-SYSRQ-14128 | Q26: oui | R26: SERYTI catalogue v1 (PROPOSED) | S26: PROPOSED
A27: ADJ-04 | B27: ADJ | C27: Dépassement rapide et serré | D27: Un véhicule dépasse le SDT très vite et très près. | E27: Highway | F27: HW-CRU, HW-FOL | G27: =IF(F27="",0,LEN(F27)-LEN(SUBSTITUTE(F27,",",""))+1) | H27: D (obligatoire) : car, pickup | I27: oui | J27: 64 | K27: 64 | L27: 0 | M27: #20 Vehicle(s) drifting, same direction | N27: H1 | O27: TC-CRAWL-179 | P27: TORC-SYSRQ-10180, TORC-SYSRQ-14128 | Q27: non | R27: SERYTI catalogue v1 (PROPOSED) | S27: PROPOSED
A28: ADJ-05 | B28: ADJ | C28: Convoi lent dans la voie adjacente | D28: Le SDT longe ou dépasse une file de véhicules lents dans la voie voisine (Foretellix « slow neighbors »). Risque : un véhicule du convoi déboîte devant le SDT. | E28: Highway | F28: HW-CRU, HW-FOL, HW-LC | G28: =IF(F28="",0,LEN(F28)-LEN(SUBSTITUTE(F28,",",""))+1) | H28: D (obligatoire) : car, tractor_trailer | I28: oui | J28: 864 | K28: 864 | L28: 0 | M28: #19 Vehicle(s) changing lanes, same direction, #20 Vehicle(s) drifting, same direction | N28: H1 | P28: TORC-SYSRQ-14128, TORC-SYSRQ-10180 | Q28: non | R28: SERYTI catalogue v1 (PROPOSED) | S28: PROPOSED | U28: §7 Slow neighbors (couvert)
A29: ADJ-06 | B29: ADJ | C29: Véhicule adjacent qui serre la ligne (lane hugger) | D29: Un véhicule voisin roule collé au marquage côté SDT sans sortir de sa voie (Foretellix « lane hugger ») : moins d'espace latéral et moins de temps pour voir un cut-in. | E29: Highway | F29: HW-CRU, HW-FOL, HW-LC | G29: =IF(F29="",0,LEN(F29)-LEN(SUBSTITUTE(F29,",",""))+1) | H29: D (optionnel) : car, tractor_trailer · hug B (optionnel) : car, tractor_trailer · hug | I29: oui | J29: 2952 | K29: 1800 | L29: 1152 | M29: #20 Vehicle(s) drifting, same direction | N29: H1 | P29: TORC-SYSRQ-14128, TORC-SYSRQ-10180 | Q29: non | R29: SERYTI catalogue v1 (PROPOSED) | S29: PROPOSED | U29: §8 Lane hugger (couvert)
A30: ADJ-07 | B30: ADJ | C30: File de véhicules arrêtés dans la voie adjacente | D30: Le SDT passe le long d'une file arrêtée dans la voie voisine (file de sortie, accident, bouchon d'une seule voie) (Foretellix « stopped vehicles »). | E30: Highway | F30: HW-CRU, HW-FOL, HW-LC | G30: =IF(F30="",0,LEN(F30)-LEN(SUBSTITUTE(F30,",",""))+1) | H30: B (obligatoire) : car, tractor_trailer | I30: oui | J30: 288 | K30: 288 | L30: 0 | M30: #19 Vehicle(s) changing lanes, same direction | N30: H1, H2 | P30: TORC-SYSRQ-14128 | Q30: non | R30: SERYTI catalogue v1 (PROPOSED) | S30: PROPOSED | U30: §10 Stopped vehicles (couvert)
A31: LC-NOM-01 | B31: LC-NOM | C31: lane change free target lane | D31: SDT changes lane into an empty target lane. Ego-only reference scenario. | E31: Highway, Urban | F31: HW-LC, URB-LC | G31: =IF(F31="",0,LEN(F31)-LEN(SUBSTITUTE(F31,",",""))+1) | H31: aucun (SDT seul) | I31: oui | J31: 48 | K31: 28 | L31: 20 | N31: H1, H4, H5 | O31: TC-CRAWL-055, TC-CRAWL-060, TC-CRAWL-067, TC-CRAWL-068, TC-CRAWL-225, TC-CRAWL-227 | P31: TORC-SYSRQ-14123, TORC-TXT-14209, TORC-SYSRQ-10197, TORC-SYSRQ-10640, TORC-SYSRQ-13836, TORC-SYSRQ-10651, TORC-SYSRQ-13830, TORC-SYSRQ-10628, TORC-SYSRQ-10648 | Q31: non | R31: SERYTI Lane Change library v0 | S31: PROPOSED
A32: LC-NOM-02 | B32: LC-NOM | C32: lane change into gap with surrounding traffic | D32: SDT changes lane into the gap between B (ahead) and D (behind) in the target lane, with A and C in the origin lane. All actors keep their speed. | E32: Highway, Urban | F32: HW-LC, URB-LC | G32: =IF(F32="",0,LEN(F32)-LEN(SUBSTITUTE(F32,",",""))+1) | H32: A (obligatoire) : car B (obligatoire) : car C (obligatoire) : car D (obligatoire) : car, tractor_trailer | I32: oui | J32: 3456 | K32: 2880 | L32: 576 | M32: #19 Vehicle(s) changing lanes, same direction | N32: H1, H2, H3, H4 | O32: TC-CRAWL-168, TC-CRAWL-169, TC-CRAWL-173, TC-CRAWL-186, TC-CRAWL-176 | P32: TORC-SYSRQ-14123, TORC-TXT-14209, TORC-SYSRQ-10197, TORC-SYSRQ-10640, TORC-SYSRQ-13836, TORC-SYSRQ-10651, TORC-SYSRQ-13830, TORC-SYSRQ-10628, TORC-SYSRQ-10649, TORC-SYSRQ-13828 | Q32: non | R32: SERYTI Lane Change library v0 | S32: PROPOSED
A33: LC-NOM-03 | B33: LC-NOM | C33: overtake slow lead | D33: A is slower than SDT in the origin lane. SDT changes lane, passes A, keeps the target lane or prepares to return. | E33: Highway | F33: HW-LC | G33: =IF(F33="",0,LEN(F33)-LEN(SUBSTITUTE(F33,",",""))+1) | H33: A (obligatoire) : car, tractor_trailer B (optionnel) : car D (optionnel) : car | I33: oui | J33: 384 | K33: 384 | L33: 0 | M33: #19 Vehicle(s) changing lanes, same direction, #25 Lead vehicle moving at lower constant speed | N33: H1, H2, H3 | O33: TC-CRAWL-134, TC-CRAWL-187, TC-CRAWL-189, TC-CRAWL-192 | P33: TORC-SYSRQ-14123, TORC-TXT-14209, TORC-SYSRQ-10197, TORC-SYSRQ-10640, TORC-SYSRQ-13836, TORC-SYSRQ-10651, TORC-SYSRQ-13830, TORC-SYSRQ-10628 | Q33: non | R33: SERYTI Lane Change library v0 | S33: PROPOSED
A34: LC-NOM-04 | B34: LC-NOM | C34: return lane after overtake | D34: After passing, SDT returns to the original lane in front of the overtaken vehicle, which is now C in the target lane. | E34: Highway | F34: HW-LC | G34: =IF(F34="",0,LEN(F34)-LEN(SUBSTITUTE(F34,",",""))+1) | H34: D (obligatoire) : car, tractor_trailer B (optionnel) : car | I34: oui | J34: 48 | K34: 48 | L34: 0 | M34: #19 Vehicle(s) changing lanes, same direction | N34: H1, H2, H3 | O34: TC-CRAWL-014, TC-CRAWL-176, TC-CRAWL-186 | P34: TORC-SYSRQ-14123, TORC-TXT-14209, TORC-SYSRQ-10197, TORC-SYSRQ-10640, TORC-SYSRQ-13836, TORC-SYSRQ-10651, TORC-SYSRQ-13830, TORC-SYSRQ-10628 | Q34: non | R34: SERYTI Lane Change library v0 | S34: PROPOSED
A35: LC-TGT-01 | B35: LC-TGT | C35: lane change with fast rear approach | D35: D approaches fast in the target lane while SDT prepares or starts the lane change. | E35: Highway, Urban | F35: HW-LC, URB-LC | G35: =IF(F35="",0,LEN(F35)-LEN(SUBSTITUTE(F35,",",""))+1) | H35: D (obligatoire) : car B (optionnel) : car | I35: oui | J35: 72 | K35: 72 | L35: 0 | M35: #19 Vehicle(s) changing lanes, same direction | N35: H1, H2, H3 | O35: TC-CRAWL-179, TC-CRAWL-175, TC-CRAWL-186, TC-CRAWL-169 | P35: TORC-SYSRQ-14123, TORC-TXT-14209, TORC-SYSRQ-10197, TORC-SYSRQ-10640, TORC-SYSRQ-13836, TORC-SYSRQ-10651, TORC-SYSRQ-13830, TORC-SYSRQ-10628, TORC-SYSRQ-10649 | Q35: non | R35: SERYTI Lane Change library v0 | S35: PROPOSED
A36: LC-TGT-02 | B36: LC-TGT | C36: lane change with simultaneous merge from far lane | D36: While SDT changes into the target lane, E in the lane beyond the target lane also changes into the same target lane. | E36: Highway | F36: HW-LC | G36: =IF(F36="",0,LEN(F36)-LEN(SUBSTITUTE(F36,",",""))+1) | H36: A (optionnel) : car B (obligatoire) : car C (optionnel) : car D (obligatoire) : car E (obligatoire) : car, pickup · lane_change_into_target F (optionnel) : car | I36: oui | J36: 448 | K36: 448 | L36: 0 | M36: #19 Vehicle(s) changing lanes, same direction | N36: H1, H4 | O36: TC-CRAWL-171, TC-CRAWL-175, TC-CRAWL-181, TC-CRAWL-184, TC-CRAWL-186 | P36: TORC-SYSRQ-14123, TORC-TXT-14209, TORC-SYSRQ-10197, TORC-SYSRQ-10640, TORC-SYSRQ-13836, TORC-SYSRQ-10651, TORC-SYSRQ-13830, TORC-SYSRQ-10628 | Q36: non | R36: SERYTI Lane Change library v0 | S36: PROPOSED
A37: LC-TGT-03 | B37: LC-TGT | C37: lane change with closing gap | D37: D accelerates to close the gap while SDT signals or starts the lane change (non-cooperative driver). | E37: Highway | F37: HW-LC, HW-ONR | G37: =IF(F37="",0,LEN(F37)-LEN(SUBSTITUTE(F37,",",""))+1) | H37: D (obligatoire) : car · accelerate B (obligatoire) : car | I37: oui | J37: 64 | K37: 64 | L37: 0 | M37: #19 Vehicle(s) changing lanes, same direction | N37: H1, H2, H3 | O37: TC-CRAWL-175, TC-CRAWL-176 | P37: TORC-SYSRQ-14123, TORC-TXT-14209, TORC-SYSRQ-10197, TORC-SYSRQ-10640, TORC-SYSRQ-13836, TORC-SYSRQ-10651, TORC-SYSRQ-13830, TORC-SYSRQ-10628, TORC-SYSRQ-10649, TORC-SYSRQ-10647 | Q37: non | R37: SERYTI Lane Change library v0 | S37: PROPOSED
A38: LC-TGT-04 | B38: LC-TGT | C38: lane change with target lead braking | D38: B brakes while SDT is moving into the target lane behind it. | E38: Highway | F38: HW-LC | G38: =IF(F38="",0,LEN(F38)-LEN(SUBSTITUTE(F38,",",""))+1) | H38: B (obligatoire) : car, tractor_trailer · brake D (obligatoire) : car | I38: oui | J38: 192 | K38: 160 | L38: 32 | M38: #19 Vehicle(s) changing lanes, same direction, #26 Lead vehicle decelerating | N38: H2, H3 | O38: TC-CRAWL-185, TC-CRAWL-176, TC-CRAWL-039 | P38: TORC-SYSRQ-14123, TORC-TXT-14209, TORC-SYSRQ-10197, TORC-SYSRQ-10640, TORC-SYSRQ-13836, TORC-SYSRQ-10651, TORC-SYSRQ-13830, TORC-SYSRQ-10628, TORC-SYSRQ-13828, TORC-SYSRQ-13835 | Q38: non | R38: SERYTI Lane Change library v0 | S38: PROPOSED
A39: LC-TGT-05 | B39: LC-TGT | C39: lane change with vehicle alongside trailer | D39: A vehicle travels alongside the SDT trailer in the target lane (D overlapping the combination), partly in the trailer blind zone. | E39: Highway | F39: HW-LC | G39: =IF(F39="",0,LEN(F39)-LEN(SUBSTITUTE(F39,",",""))+1) | H39: D (obligatoire) : car, pickup | I39: oui | J39: 64 | K39: 64 | L39: 0 | M39: #19 Vehicle(s) changing lanes, same direction, #20 Vehicle(s) drifting, same direction | N39: H1, H2, H3 | O39: TC-CRAWL-014, TC-CRAWL-186, TC-CRAWL-193, TC-CRAWL-012 | P39: TORC-SYSRQ-14123, TORC-TXT-14209, TORC-SYSRQ-10197, TORC-SYSRQ-10640, TORC-SYSRQ-13836, TORC-SYSRQ-10651, TORC-SYSRQ-13830, TORC-SYSRQ-10628, TORC-SYSRQ-14128, TORC-SYSRQ-10182 | Q39: non | R39: SERYTI Lane Change library v0 | S39: PROPOSED
A40: LC-TGT-06 | B40: LC-TGT | C40: lane change with motorcycle in blind spot | D40: A motorcycle is in the target lane in the SDT blind zone or lane-splitting. | E40: Highway | F40: HW-LC | G40: =IF(F40="",0,LEN(F40)-LEN(SUBSTITUTE(F40,",",""))+1) | H40: D (obligatoire) : motorcycle | I40: oui | J40: 32 | K40: 32 | L40: 0 | M40: #19 Vehicle(s) changing lanes, same direction, #20 Vehicle(s) drifting, same direction | N40: H1 | O40: TC-CRAWL-200, TC-CRAWL-201 | P40: TORC-SYSRQ-14123, TORC-TXT-14209, TORC-SYSRQ-10197, TORC-SYSRQ-10640, TORC-SYSRQ-13836, TORC-SYSRQ-10651, TORC-SYSRQ-13830, TORC-SYSRQ-10628, TORC-SYSRQ-14128 | Q40: oui | R40: SERYTI Lane Change library v0 | S40: PROPOSED
A41: LC-TGT-07 | B41: LC-TGT | C41: lane change next to large or unstable vehicle | D41: Target lane contains a wide load or a truck with a swaying trailer next to the gap. | E41: Highway | F41: HW-LC, HW-CRU, HW-FOL | G41: =IF(F41="",0,LEN(F41)-LEN(SUBSTITUTE(F41,",",""))+1) | H41: B (obligatoire) : wide_load, tractor_trailer D (optionnel) : car | I41: oui | J41: 192 | K41: 144 | L41: 48 | M41: #20 Vehicle(s) drifting, same direction | N41: H1 | O41: TC-CRAWL-187, TC-CRAWL-188, TC-CRAWL-189, TC-CRAWL-192, TC-CRAWL-191 | P41: TORC-SYSRQ-14123, TORC-TXT-14209, TORC-SYSRQ-10197, TORC-SYSRQ-10640, TORC-SYSRQ-13836, TORC-SYSRQ-10651, TORC-SYSRQ-13830, TORC-SYSRQ-10628, TORC-SYSRQ-14128 | Q41: non | R41: SERYTI Lane Change library v0 | S41: PROPOSED
...

Sheet Matrice
A1: Matrice Behavior × Abstract
A2: Lettre = intention du SDT pour ce behavior (K, L, M, S, I, E). « 2 » = lien prévu, génération au jalon 2.
A4: ID | B4: Abstract | C4: HW-CRU | D4: HW-FOL | E4: HW-LC | F4: HW-ONR | G4: HW-OFR | H4: HW-CSS | I4: HW-ESL | J4: HW-ELM | K4: URB-CRU | L4: URB-FOL | M4: URB-LC | N4: URB-XWK | O4: URB-TRN | P4: URB-STR | Q4: URB-SIL | R4: URB-ELM | S4: HUB-LSD | T4: HUB-DCK | U4: HUB-PUL | V4: HUB-AVD | W4: HUB-EST | X4: Nb behaviors
A5: LV · Véhicule leader dans la voie du SDT
A6: LV-01 | B6: Route libre, aucun leader | C6: K | K6: K | X6: =COUNTA(C6:W6)
A7: LV-02 | B7: Leader plus lent à vitesse constante | C7: K | D7: K | L7: K | X7: =COUNTA(C7:W7)
A8: LV-03 | B8: Leader qui décélère modérément | D8: K | L8: K | X8: =COUNTA(C8:W8)
A9: LV-04 | B9: Leader qui freine fort | D9: K | I9: I | J9: E | L9: K | X9: =COUNTA(C9:W9)
A10: LV-05 | B10: Leader arrêté (fin de bouchon, véhicule arrêté) | C10: K | D10: K | E10: L | I10: I | J10: E | L10: K | X10: =COUNTA(C10:W10)
A11: LV-06 | B11: Leader qui accélère et s'éloigne | D11: K | L11: K | X11: =COUNTA(C11:W11)
A12: LV-07 | B12: Accordéon (stop-and-go) | D12: K | L12: K | X12: =COUNTA(C12:W12)
A13: LV-08 | B13: Leader au comportement erratique | D13: K | X13: =COUNTA(C13:W13)
A14: LV-09 | B14: Moto en leader | C14: K | D14: K | X14: =COUNTA(C14:W14)
A15: LV-10 | B15: Leader camion qui masque la vue | D15: K | I15: I | X15: =COUNTA(C15:W15)
A16: LV-11 | B16: Le leader change de voie et libère la voie (cut-out) | C16: K | D16: K | X16: =COUNTA(C16:W16)
A17: CI · Insertion devant le SDT (cut-in)
A18: CI-01 | B18: Cut-in depuis la gauche, gap suffisant | C18: K | D18: K | L18: K | X18: =COUNTA(C18:W18)
A19: CI-02 | B19: Cut-in serré depuis la gauche | C19: K | D19: K | I19: I | X19: =COUNTA(C19:W19)
A20: CI-03 | B20: Cut-in depuis la droite | C20: K | D20: K | X20: =COUNTA(C20:W20)
A21: CI-04 | B21: Cut-in d'un véhicule plus lent | C21: K | D21: K | X21: =COUNTA(C21:W21)
A22: CI-05 | B22: Cut-in d'un semi-remorque | C22: K | D22: K | X22: =COUNTA(C22:W22)
A23: CI-06 | B23: Insertion depuis la bretelle devant le SDT | C23: K | D23: K | X23: =COUNTA(C23:W23)
A24: CI-07 | B24: Brake-check après un rabattement | D24: K | I24: I | X24: =COUNTA(C24:W24)
A25: CI-08 | B25: Deux véhicules se rabattent l'un après l'autre | C25: K | D25: K | X25: =COUNTA(C25:W25)
A26: ADJ · Véhicules adjacents
A27: ADJ-01 | B27: Véhicule adjacent qui dérive vers le SDT | C27: K | D27: K | J27: E | X27: =COUNTA(C27:W27)
A28: ADJ-02 | B28: Semi adjacent dont la remorque louvoie | C28: K | D28: K | X28: =COUNTA(C28:W28)
A29: ADJ-03 | B29: Moto qui remonte les files | C29: K | D29: K | X29: =COUNTA(C29:W29)
A30: ADJ-04 | B30: Dépassement rapide et serré | C30: K | D30: K | X30: =COUNTA(C30:W30)
A31: ADJ-05 | B31: Convoi lent dans la voie adjacente | C31: K | D31: K | E31: L | X31: =COUNTA(C31:W31)
A32: ADJ-06 | B32: Véhicule adjacent qui serre la ligne (lane hugger) | C32: K | D32: K | E32: L | X32: =COUNTA(C32:W32)
A33: ADJ-07 | B33: File de véhicules arrêtés dans la voie adjacente | C33: K | D33: K | E33: L | X33: =COUNTA(C33:W33)
A34: LC-NOM · Changement de voie nominal
A35: LC-NOM-01 | B35: lane change free target lane | E35: L | M35: L | X35: =COUNTA(C35:W35)
A36: LC-NOM-02 | B36: lane change into gap with surrounding traffic | E36: L | M36: L | X36: =COUNTA(C36:W36)
A37: LC-NOM-03 | B37: overtake slow lead | E37: L | X37: =COUNTA(C37:W37)
A38: LC-NOM-04 | B38: return lane after overtake | E38: L | X38: =COUNTA(C38:W38)
A39: LC-TGT · Trafic dans la voie cible
A40: LC-TGT-01 | B40: lane change with fast rear approach | E40: L | M40: L | X40: =COUNTA(C40:W40)
A41: LC-TGT-02 | B41: lane change with simultaneous merge from far lane | E41: L | X41: =COUNTA(C41:W41)
...

Sheet Behaviors
A1: Behaviors (Behavior Table Jama) et leur catalogue
A2: Définition Jama : export « Driver Out 2026 SDT Requirements » du 26/03/2026 (Highway seulement).
A4: Code | B4: Use case | C4: Behavior | D4: DDT / DDT-F | E4: Catégories | F4: Intention du SDT | G4: Définition Jama | H4: Statut Jama | I4: Nb abstracts | J4: Concrets retenus | K4: Texte de la définition
A5: HW-CRU | B5: Highway | C5: Lane-Centered Cruise | D5: DDT | E5: Safety, Traffic compliance | F5: keep_lane | G5: TORC-SYSRQ-10155 | H5: Review | I5: =Matrice!C143 | J5: 6480 | K5: Maintain steady longitudinal speed and lateral position within the current lane on a highway when no immediate interaction, routing, or tactical maneuver is required. This is the default steady-state driving behavior. Intent Maintain progress while complying with traffic rules and ensuring dynamic stability. Entry Condition SDT is in robotic mode. SDT is on a highway lane segment with valid lane geometry. SDT is driving in a lane with visible lane markings on both sides of the SDT. Interior lane width is greater than or equal to 3.5 m. Minimum horizontal radius of curvature is 450 m. No lead vehicle requiring active following behavior within engagement distance. No mandatory routing event (exit, merge, lane drop) within the planning horizon. No higher-priority interaction or fallback behavior is active. Exit Condition A lead vehicle enters the following engagement range. A mandatory or discretionary lane change becomes active. An on-ramp merge, off-ramp exit, or hazard requires behavior transition. System health degradation requires fallback (includes unclear lane marking/ low confidence in Lane marking perception). Out of ODD conditions.
A6: HW-FOL | B6: Highway | C6: Lane-Centered Adaptive Follow | D6: DDT | E6: Safety, Efficiency | F6: keep_lane | G6: TORC-SYSRQ-14122 | H6: Draft | I6: =Matrice!D143 | J6: 7422 | K6: Description Regulate longitudinal motion to maintain a safe, comfortable, and legally compliant distance behind a lead vehicle traveling in the same lane. Intent Reduce collision risk while maintaining reasonable traffic flow and compliance with following-distance expectations. Entry Condition A lead vehicle is detected and tracked in the ego lane with sufficient confidence. Headway or distance falls below the cruise disengagement threshold. Ego vehicle remains lane-aligned with the lead vehicle. Exit Condition Lead vehicle exits the lane or exceeds disengagement distance. Ego initiates a lane change or overtake. Route event or merge/exit behavior becomes active. Tracking confidence drops below acceptable threshold.
A7: HW-LC | B7: Highway | C7: Lane Changes / Overtaking | D7: DDT | E7: Safety, Traffic compliance, Efficiency, Courtesy | F7: lane_change | G7: TORC-SYSRQ-14123 | H7: Draft | I7: =Matrice!E143 | J7: 8650 | K7: Description Transition laterally to an adjacent lane to improve progress or satisfy routing requirements, including gap assessment, signaling, execution, and stabilization. Intent Improve progress or satisfy route constraints while maintaining safety, legality, and predictability. Entry Condition Adjacent lane exists and lane change is permitted. Discretionary trigger: lead vehicle significantly slower than desired speed. Mandatory trigger: lane drop, exit preparation, or obstacle ahead. Adjacent-lane traffic is sufficiently observable for gap assessment. Exit Condition Ego vehicle is fully established and stable in the target lane. Lane change is safely aborted and ego remains in original lane. Behavior transitions into adaptive follow or lane-centered cruise.
A8: HW-ONR | B8: Highway | C8: On-Ramp Merge | D8: DDT | E8: Safety, Traffic compliance, Efficiency, Courtesy | F8: lane_change | G8: TORC-SYSRQ-14124 | H8: Draft | I8: =Matrice!F143 | J8: 3296 | K8: Description Enter highway mainline traffic from an on-ramp by identifying a suitable gap, adjusting speed accordingly, and merging laterally within the merge zone. Intent Join the highway flow safely, legally and efficiently while minimizing disruption to mainline traffic. Entry Condition Ego vehicle is on an on-ramp approaching a merge area. Mainline traffic is detected and tracked with sufficient confidence. Route requires highway entry. Ego vehicle is capable of reaching the entry ramp lane within safe bounds. Exit Condition Ego vehicle is fully merged and stabilized in the mainline lane (transitions to Lane-Centered Cruise or Adaptive Follow). Merge is aborted and ego vehicle reaches desired safe state (stops or holds at end of acceleration lane or pulls over to the should if shoulder available). Emergency maneuver is triggered.
A9: HW-OFR | B9: Highway | C9: Off-Ramp Exit | D9: DDT | E9: Safety, Courtesy | F9: lane_change | G9: TORC-SYSRQ-14125 | H9: Draft | I9: =Matrice!G143 | J9: 588 | K9: Description Navigate the ego vehicle from the mainline highway lane into an off-ramp exit lane, following the planned route and executing the lateral transition within the designated exit zone. Intent Exit the highway safely and predictably, maintaining compliance with lane geometry and speed limits. Entry Condition Route plan requires the next off-ramp exit. Ego vehicle is within the pre-exit planning horizon. Off-ramp entry geometry is detected and confirmed. Ego vehicle is capable of reaching the exit lane within safe bounds. Exit Condition Ego vehicle is fully positioned in the off-ramp lane and decelerating (behavior transitions to urban or surface street behavior). Exit is missed and a re-route is required. Emergency maneuver preempts the exit.
A10: HW-CSS | B10: Highway | C10: Controlled Stop on Shoulder | D10: DDT-F | E10: Safety, Traffic compliance | F10: stop_on_shoulder | G10: TORC-SYSRQ-14127 | H10: Draft | I10: =Matrice!H143 | J10: 932 | K10: Description Execute a controlled, deliberate deceleration and lateral transition to bring the ego vehicle to a stop on the highway shoulder or emergency stopping lane, in response to a planned or reactive need to exit the travel lane safely. Intent Bring the vehicle to a safe, stable stop outside the travel lane with minimal risk to occupants and other road users. Entry Condition A DDT-F condition or planned stop event requires the ego to exit the travel lane. A shoulder or emergency stopping area is available and geometrically valid. No higher-priority emergency maneuver is active. Exit Condition Shoulder or emergency stopping area is blocked or unavailable. Ego vehicle resumes travel lane behavior after stopping related condition is cleared. Another emergency maneuver overrides the controlled stop.
A11: HW-ESL | B11: Highway | C11: Emergency Stop in Lane | D11: DDT-F | E11: Safety | F11: stop_in_lane | G11: TORC-SYSRQ-14126 | H11: Review | I11: =Matrice!I143 | J11: 872 | K11: Description Execute an immediate, controlled deceleration to bring the ego vehicle to a stop within its current travel lane in response to a critical failure or imminent hazard that precludes transitioning to Stop on shoulder. Intent Bring the vehicle to a safe stop as quickly as practicable while minimizing collision risk. Entry Condition A critical DDT-F condition requires an immediate stop and shoulder transition is not possible. A hazard or system failure precludes continued travel. Exit Condition Ego vehicle is stopped in lane with hazard lights active. Ego vehicle resumes travel lane behavior after stopping related condition is cleared. Another emergency maneuver overrides the controlled stop. Emergency services or remote operator intervention is signaled. Link to Behavior Page: https://torc.atlassian.net/wiki/pages/resumedraft.action?draftId=2915696704
A12: HW-ELM | B12: Highway | C12: Emergency Lateral Motion | D12: DDT-F | E12: Safety, Traffic compliance | F12: emergency_lateral | I12: =Matrice!J143 | J12: 368
A13: URB-CRU | B13: Urban | C13: Lane-Centered Cruise | D13: DDT | E13: Safety, Traffic compliance | F13: keep_lane | I13: =Matrice!K143 | J13: 122
A14: URB-FOL | B14: Urban | C14: Lane-Centered Adaptive Follow | D14: DDT | E14: Safety, Traffic compliance | F14: keep_lane | I14: =Matrice!L143 | J14: 1040
A15: URB-LC | B15: Urban | C15: Lane Changes / Overtaking | D15: DDT | E15: Safety, Traffic compliance | F15: lane_change | I15: =Matrice!M143 | J15: 1730
A16: URB-XWK | B16: Urban | C16: Crosswalk Yield | D16: DDT | E16: Safety, Traffic compliance, Courtesy | F16: keep_lane | I16: =Matrice!N143 | J16: 0
A17: URB-TRN | B17: Urban | C17: Protected/Unprotected Turn at Intersection | D17: DDT | E17: Safety, Traffic compliance, Courtesy | F17: keep_lane | I17: =Matrice!O143 | J17: 0
A18: URB-STR | B18: Urban | C18: Going Straight through Protected/Unprotected Intersection | D18: DDT | E18: Safety, Traffic compliance, Courtesy | F18: keep_lane | I18: =Matrice!P143 | J18: 0
A19: URB-SIL | B19: Urban | C19: Stop in Lane | D19: DDT / DDT-F | E19: Safety, Traffic compliance | F19: stop_in_lane | I19: =Matrice!Q143 | J19: 20
A20: URB-ELM | B20: Urban | C20: Emergency Lateral Motion | D20: DDT-F | E20: Safety, Traffic compliance, Courtesy | F20: emergency_lateral | I20: =Matrice!R143 | J20: 0
A21: HUB-LSD | B21: Hub | C21: Low-Speed Driving | D21: DDT | E21: Safety, Traffic compliance | F21: keep_lane | I21: =Matrice!S143 | J21: 0
A22: HUB-DCK | B22: Hub | C22: Docking / Parking | D22: DDT | E22: Safety, Efficiency | F22: keep_lane | I22: =Matrice!T143 | J22: 0
A23: HUB-PUL | B23: Hub | C23: Pull-Out / Departure | D23: DDT | E23: Safety, Efficiency, Courtesy | F23: keep_lane | I23: =Matrice!U143 | J23: 0
A24: HUB-AVD | B24: Hub | C24: Asset Avoidance / Shared-Space Crawl | D24: DDT | E24: Safety, Efficiency | F24: keep_lane | I24: =Matrice!V143 | J24: 0
A25: HUB-EST | B25: Hub | C25: Emergency Stop | D25: DDT | E25: Safety, Traffic compliance, Efficiency | F25: stop_in_lane | I25: =Matrice!W143 | J25: 0

Sheet Justification HIRE
A1: Justification de chaque lien abstract → behavior par le HIRE v2
A2: Une ligne par lien. Lignes HIRE : les premières sont celles de la condition ODD de l'abstract, puis les conditions nominales.
A4: Abstract | B4: Titre | C4: Behavior | D4: Niveau | E4: Origine du lien | F4: Pourquoi | G4: Hazards | H4: Commandes sollicitées | I4: Nb lignes HIRE | J4: Lignes HIRE v2 (10 premières) | K4: HFS | L4: Condition ODD dans le HIRE | M4: Condition ODD absente du HIRE
A5: LV-01 | B5: Route libre, aucun leader | C5: HW-CRU | D5: justifié | E5: catalogue SERYTI | F5: Le HIRE de HW-CRU relie une déviation de commande sollicitée par la scène (Steering command) au hazard de l'abstract (H1, H5) | G5: H1 Side collision, H5 Loss of stability / control | H5: Steering command | I5: 40 | J5: HW_ Lane-Centered Cruise_Excessive Steering_01 HW_ Lane-Centered Cruise_Excessive Steering_02 HW_ Lane-Centered Cruise_Excessive Steering_03 HW_ Lane-Centered Cruise_Excessive Steering_04 HW_ Lane-Centered Cruise_Insufficient Steering_01 HW_ Lane-Centered Cruise_Insufficient Steering_03 HW_ Lane-Centered Cruise_Insufficient Steering_04 HW_ Lane-Centered Cruise_No Steering_01 HW_ Lane-Centered Cruise_No Steering_03 HW_ Lane-Centered Cruise_No Steering_04 | K5: HFS-029, HFS-033
A6: LV-01 | B6: Route libre, aucun leader | C6: URB-CRU | D6: justifié | E6: catalogue SERYTI | F6: Le HIRE de URB-CRU relie une déviation de commande sollicitée par la scène (Steering command) au hazard de l'abstract (H1, H5) | G6: H1 Side collision, H5 Loss of stability / control | H6: Steering command | I6: 20 | J6: URB_ Lane-Centered Cruise_Excessive Steering_01 URB_ Lane-Centered Cruise_Excessive Steering_02 URB_ Lane-Centered Cruise_Excessive Steering_03 URB_ Lane-Centered Cruise_Excessive Steering_04 URB_ Lane-Centered Cruise_Insufficient Steering_01 URB_ Lane-Centered Cruise_Insufficient Steering_03 URB_ Lane-Centered Cruise_Insufficient Steering_04 URB_ Lane-Centered Cruise_No Steering_01 URB_ Lane-Centered Cruise_No Steering_03 URB_ Lane-Centered Cruise_No Steering_04 | K6: HFS-075, HFS-079
A7: LV-02 | B7: Leader plus lent à vitesse constante | C7: HW-CRU | D7: justifié | E7: catalogue SERYTI | F7: Le HIRE de HW-CRU relie une déviation de commande sollicitée par la scène (Acceleration command, Deceleration command) au hazard de l'abstract (H2) | G7: H2 Front collision | H7: Acceleration command, Deceleration command | I7: 17 | J7: HW_ Lane-Centered Cruise_Excessive Acceleration_01 HW_ Lane-Centered Cruise_Excessive Acceleration_02 HW_ Lane-Centered Cruise_Excessive Acceleration_04 HW_ Lane-Centered Cruise_Insufficient Deceleration_01 HW_ Lane-Centered Cruise_Insufficient Deceleration_03 HW_ Lane-Centered Cruise_No Deceleration_01 HW_ Lane-Centered Cruise_No Deceleration_04 HW_ Lane-Centered Cruise_Unintended Acceleration_01 HW_ Lane-Centered Cruise_Unintended Acceleration_02 HW_ Lane-Centered Cruise_Unintended Acceleration_04 | K7: HFS-030
A8: LV-02 | B8: Leader plus lent à vitesse constante | C8: HW-FOL | D8: justifié | E8: catalogue SERYTI | F8: Le HIRE de HW-FOL relie une déviation de commande sollicitée par la scène (Acceleration command, Deceleration command) au hazard de l'abstract (H2) | G8: H2 Front collision | H8: Acceleration command, Deceleration command | I8: 24 | J8: HW_ Lane-Centered Adaptive Follow_Excessive Acceleration_01 HW_ Lane-Centered Adaptive Follow_Excessive Acceleration_02 HW_ Lane-Centered Adaptive Follow_Excessive Acceleration_04 HW_ Lane-Centered Adaptive Follow_Insufficient Deceleration_01 HW_ Lane-Centered Adaptive Follow_Insufficient Deceleration_03 HW_ Lane-Centered Adaptive Follow_No Deceleration_01 HW_ Lane-Centered Adaptive Follow_No Deceleration_04 HW_ Lane-Centered Adaptive Follow_Unintended Acceleration_01 HW_ Lane-Centered Adaptive Follow_Unintended Acceleration_02 HW_ Lane-Centered Adaptive Follow_Unintended Acceleration_04 | K8: HFS-025
A9: LV-02 | B9: Leader plus lent à vitesse constante | C9: URB-FOL | D9: justifié | E9: catalogue SERYTI | F9: Le HIRE de URB-FOL relie une déviation de commande sollicitée par la scène (Acceleration command, Deceleration command) au hazard de l'abstract (H2) | G9: H2 Front collision | H9: Acceleration command, Deceleration command | I9: 10 | J9: URB_ Lane-Centered Adaptive Follow_Excessive Acceleration_01 URB_ Lane-Centered Adaptive Follow_Excessive Acceleration_02 URB_ Lane-Centered Adaptive Follow_Excessive Acceleration_04 URB_ Lane-Centered Adaptive Follow_Insufficient Deceleration_01 URB_ Lane-Centered Adaptive Follow_Insufficient Deceleration_03 URB_ Lane-Centered Adaptive Follow_No Deceleration_01 URB_ Lane-Centered Adaptive Follow_No Deceleration_04 URB_ Lane-Centered Adaptive Follow_Unintended Acceleration_01 URB_ Lane-Centered Adaptive Follow_Unintended Acceleration_02 URB_ Lane-Centered Adaptive Follow_Unintended Acceleration_04 | K9: HFS-071
A10: LV-03 | B10: Leader qui décélère modérément | C10: HW-FOL | D10: justifié | E10: catalogue SERYTI | F10: Le HIRE de HW-FOL relie une déviation de commande sollicitée par la scène (Acceleration command, Deceleration command) au hazard de l'abstract (H2) | G10: H2 Front collision | H10: Acceleration command, Brake Lights command, Deceleration command | I10: 24 | J10: HW_ Lane-Centered Adaptive Follow_Excessive Acceleration_01 HW_ Lane-Centered Adaptive Follow_Excessive Acceleration_02 HW_ Lane-Centered Adaptive Follow_Excessive Acceleration_04 HW_ Lane-Centered Adaptive Follow_Insufficient Deceleration_01 HW_ Lane-Centered Adaptive Follow_Insufficient Deceleration_03 HW_ Lane-Centered Adaptive Follow_No Deceleration_01 HW_ Lane-Centered Adaptive Follow_No Deceleration_04 HW_ Lane-Centered Adaptive Follow_Unintended Acceleration_01 HW_ Lane-Centered Adaptive Follow_Unintended Acceleration_02 HW_ Lane-Centered Adaptive Follow_Unintended Acceleration_04 | K10: HFS-025
A11: LV-03 | B11: Leader qui décélère modérément | C11: URB-FOL | D11: justifié | E11: catalogue SERYTI | F11: Le HIRE de URB-FOL relie une déviation de commande sollicitée par la scène (Acceleration command, Deceleration command) au hazard de l'abstract (H2) | G11: H2 Front collision | H11: Acceleration command, Brake Lights command, Deceleration command | I11: 10 | J11: URB_ Lane-Centered Adaptive Follow_Excessive Acceleration_01 URB_ Lane-Centered Adaptive Follow_Excessive Acceleration_02 URB_ Lane-Centered Adaptive Follow_Excessive Acceleration_04 URB_ Lane-Centered Adaptive Follow_Insufficient Deceleration_01 URB_ Lane-Centered Adaptive Follow_Insufficient Deceleration_03 URB_ Lane-Centered Adaptive Follow_No Deceleration_01 URB_ Lane-Centered Adaptive Follow_No Deceleration_04 URB_ Lane-Centered Adaptive Follow_Unintended Acceleration_01 URB_ Lane-Centered Adaptive Follow_Unintended Acceleration_02 URB_ Lane-Centered Adaptive Follow_Unintended Acceleration_04 | K11: HFS-071
A12: LV-04 | B12: Leader qui freine fort | C12: HW-FOL | D12: justifié | E12: catalogue SERYTI | F12: Le HIRE de HW-FOL relie une déviation de commande sollicitée par la scène (Acceleration command, Deceleration command) au hazard de l'abstract (H2) | G12: H2 Front collision | H12: Acceleration command, Brake Lights command, Deceleration command | I12: 24 | J12: HW_ Lane-Centered Adaptive Follow_Excessive Acceleration_01 HW_ Lane-Centered Adaptive Follow_Excessive Acceleration_02 HW_ Lane-Centered Adaptive Follow_Excessive Acceleration_04 HW_ Lane-Centered Adaptive Follow_Insufficient Deceleration_01 HW_ Lane-Centered Adaptive Follow_Insufficient Deceleration_03 HW_ Lane-Centered Adaptive Follow_No Deceleration_01 HW_ Lane-Centered Adaptive Follow_No Deceleration_04 HW_ Lane-Centered Adaptive Follow_Unintended Acceleration_01 HW_ Lane-Centered Adaptive Follow_Unintended Acceleration_02 HW_ Lane-Centered Adaptive Follow_Unintended Acceleration_04 | K12: HFS-025
A13: LV-04 | B13: Leader qui freine fort | C13: HW-ESL | D13: justifié | E13: catalogue SERYTI | F13: Le HIRE de HW-ESL relie une déviation de commande sollicitée par la scène (Acceleration command, Deceleration command) au hazard de l'abstract (H2) | G13: H2 Front collision | H13: Acceleration command, Brake Lights command, Deceleration command, Hazard Lights command | I13: 4 | J13: HW_ Emergency Stop in Lane_Excessive Acceleration_01 HW_ Emergency Stop in Lane_No Deceleration_01 HW_ Emergency Stop in Lane_No Deceleration_03 HW_ Emergency Stop in Lane_Unintended Acceleration_01 | K13: HFS-015
A14: LV-04 | B14: Leader qui freine fort | C14: HW-ELM | D14: justifié | E14: catalogue SERYTI | F14: Le HIRE de HW-ELM relie une déviation de commande sollicitée par la scène (Acceleration command, Deceleration command) au hazard de l'abstract (H2) | G14: H2 Front collision | H14: Acceleration command, Brake Lights command, Deceleration command, Hazard Lights command, Steering command, Turn Signal command | I14: 4 | J14: HW_ Emergency Lateral Motion_Excessive Acceleration_01 HW_ Emergency Lateral Motion_No Deceleration_01 HW_ Emergency Lateral Motion_No Deceleration_03 HW_ Emergency Lateral Motion_Unintended Acceleration_01 | K14: HFS-009
A15: LV-04 | B15: Leader qui freine fort | C15: URB-FOL | D15: justifié | E15: catalogue SERYTI | F15: Le HIRE de URB-FOL relie une déviation de commande sollicitée par la scène (Acceleration command, Deceleration command) au hazard de l'abstract (H2) | G15: H2 Front collision | H15: Acceleration command, Brake Lights command, Deceleration command | I15: 10 | J15: URB_ Lane-Centered Adaptive Follow_Excessive Acceleration_01 URB_ Lane-Centered Adaptive Follow_Excessive Acceleration_02 URB_ Lane-Centered Adaptive Follow_Excessive Acceleration_04 URB_ Lane-Centered Adaptive Follow_Insufficient Deceleration_01 URB_ Lane-Centered Adaptive Follow_Insufficient Deceleration_03 URB_ Lane-Centered Adaptive Follow_No Deceleration_01 URB_ Lane-Centered Adaptive Follow_No Deceleration_04 URB_ Lane-Centered Adaptive Follow_Unintended Acceleration_01 URB_ Lane-Centered Adaptive Follow_Unintended Acceleration_02 URB_ Lane-Centered Adaptive Follow_Unintended Acceleration_04 | K15: HFS-071
A16: LV-05 | B16: Leader arrêté (fin de bouchon, véhicule arrêté) | C16: HW-CRU | D16: justifié | E16: catalogue SERYTI | F16: Le HIRE de HW-CRU relie une déviation de commande sollicitée par la scène (Acceleration command, Deceleration command) au hazard de l'abstract (H2) | G16: H2 Front collision | H16: Acceleration command, Brake Lights command, Deceleration command | I16: 17 | J16: HW_ Lane-Centered Cruise_Deceleration too late_03 HW_ Lane-Centered Cruise_Excessive Acceleration_01 HW_ Lane-Centered Cruise_Excessive Acceleration_02 HW_ Lane-Centered Cruise_Excessive Acceleration_04 HW_ Lane-Centered Cruise_Insufficient Deceleration_01 HW_ Lane-Centered Cruise_Insufficient Deceleration_03 HW_ Lane-Centered Cruise_No Deceleration_01 HW_ Lane-Centered Cruise_No Deceleration_04 HW_ Lane-Centered Cruise_Unintended Acceleration_01 HW_ Lane-Centered Cruise_Unintended Acceleration_02 | K16: HFS-030 | L16: [Out-of-ODD] Disabled / stopped vehicle in lane or shoulder
A17: LV-05 | B17: Leader arrêté (fin de bouchon, véhicule arrêté) | C17: HW-FOL | D17: justifié | E17: catalogue SERYTI | F17: Le HIRE de HW-FOL relie une déviation de commande sollicitée par la scène (Acceleration command, Deceleration command) au hazard de l'abstract (H2) | G17: H2 Front collision | H17: Acceleration command, Brake Lights command, Deceleration command | I17: 24 | J17: HW_ Lane-Centered Adaptive Follow_Excessive Acceleration_01 HW_ Lane-Centered Adaptive Follow_Excessive Acceleration_02 HW_ Lane-Centered Adaptive Follow_Excessive Acceleration_04 HW_ Lane-Centered Adaptive Follow_Insufficient Deceleration_01 HW_ Lane-Centered Adaptive Follow_Insufficient Deceleration_03 HW_ Lane-Centered Adaptive Follow_No Deceleration_01 HW_ Lane-Centered Adaptive Follow_No Deceleration_04 HW_ Lane-Centered Adaptive Follow_Unintended Acceleration_01 HW_ Lane-Centered Adaptive Follow_Unintended Acceleration_02 HW_ Lane-Centered Adaptive Follow_Unintended Acceleration_04 | K17: HFS-025 | M17: [Out-of-ODD] Disabled / stopped vehicle in lane or shoulder
A18: LV-05 | B18: Leader arrêté (fin de bouchon, véhicule arrêté) | C18: HW-ESL | D18: justifié | E18: catalogue SERYTI | F18: Le HIRE de HW-ESL relie une déviation de commande sollicitée par la scène (Acceleration command, Deceleration command) au hazard de l'abstract (H2) | G18: H2 Front collision | H18: Acceleration command, Brake Lights command, Deceleration command, Hazard Lights command | I18: 4 | J18: HW_ Emergency Stop in Lane_Excessive Acceleration_01 HW_ Emergency Stop in Lane_No Deceleration_01 HW_ Emergency Stop in Lane_No Deceleration_03 HW_ Emergency Stop in Lane_Unintended Acceleration_01 | K18: HFS-015 | M18: [Out-of-ODD] Disabled / stopped vehicle in lane or shoulder
A19: LV-05 | B19: Leader arrêté (fin de bouchon, véhicule arrêté) | C19: HW-ELM | D19: justifié | E19: catalogue SERYTI | F19: Le HIRE de HW-ELM relie une déviation de commande sollicitée par la scène (Acceleration command, Deceleration command) au hazard de l'abstract (H2) | G19: H2 Front collision | H19: Acceleration command, Brake Lights command, Deceleration command, Hazard Lights command, Steering command, Turn Signal command | I19: 4 | J19: HW_ Emergency Lateral Motion_Excessive Acceleration_01 HW_ Emergency Lateral Motion_No Deceleration_01 HW_ Emergency Lateral Motion_No Deceleration_03 HW_ Emergency Lateral Motion_Unintended Acceleration_01 | K19: HFS-009 | M19: [Out-of-ODD] Disabled / stopped vehicle in lane or shoulder
A20: LV-05 | B20: Leader arrêté (fin de bouchon, véhicule arrêté) | C20: HW-LC | D20: justifié | E20: catalogue SERYTI | F20: Le HIRE de HW-LC relie une déviation de commande sollicitée par la scène (Acceleration command, Deceleration command, Steering command) au hazard de l'abstract (H2) | G20: H2 Front collision | H20: Acceleration command, Brake Lights command, Deceleration command, Steering command, Turn Signal command | I20: 11 | J20: HW_ Lane Changes / Overtaking_Excessive Acceleration_01 HW_ Lane Changes / Overtaking_Excessive Acceleration_02 HW_ Lane Changes / Overtaking_Excessive Acceleration_04 HW_ Lane Changes / Overtaking_Insufficient Deceleration_01 HW_ Lane Changes / Overtaking_Insufficient Deceleration_03 HW_ Lane Changes / Overtaking_No Deceleration_01 HW_ Lane Changes / Overtaking_No Deceleration_04 HW_ Lane Changes / Overtaking_No Steering_02 HW_ Lane Changes / Overtaking_Unintended Acceleration_01 HW_ Lane Changes / Overtaking_Unintended Acceleration_02 | K20: HFS-020 | M20: [Out-of-ODD] Disabled / stopped vehicle in lane or shoulder
A21: LV-05 | B21: Leader arrêté (fin de bouchon, véhicule arrêté) | C21: URB-FOL | D21: justifié | E21: catalogue SERYTI | F21: Le HIRE de URB-FOL relie une déviation de commande sollicitée par la scène (Acceleration command, Deceleration command) au hazard de l'abstract (H2) | G21: H2 Front collision | H21: Acceleration command, Brake Lights command, Deceleration command | I21: 10 | J21: URB_ Lane-Centered Adaptive Follow_Excessive Acceleration_01 URB_ Lane-Centered Adaptive Follow_Excessive Acceleration_02 URB_ Lane-Centered Adaptive Follow_Excessive Acceleration_04 URB_ Lane-Centered Adaptive Follow_Insufficient Deceleration_01 URB_ Lane-Centered Adaptive Follow_Insufficient Deceleration_03 URB_ Lane-Centered Adaptive Follow_No Deceleration_01 URB_ Lane-Centered Adaptive Follow_No Deceleration_04 URB_ Lane-Centered Adaptive Follow_Unintended Acceleration_01 URB_ Lane-Centered Adaptive Follow_Unintended Acceleration_02 URB_ Lane-Centered Adaptive Follow_Unintended Acceleration_04 | K21: HFS-071 | M21: [Out-of-ODD] Disabled / stopped vehicle in lane or shoulder
A22: LV-06 | B22: Leader qui accélère et s'éloigne | C22: HW-FOL | D22: justifié | E22: catalogue SERYTI | F22: Le HIRE de HW-FOL relie une déviation de commande sollicitée par la scène (Acceleration command, Deceleration command) au hazard de l'abstract (H2, H3) | G22: H2 Front collision, H3 Rear-end by follower | H22: Acceleration command, Deceleration command | I22: 35 | J22: HW_ Lane-Centered Adaptive Follow_Excessive Acceleration_01 HW_ Lane-Centered Adaptive Follow_Excessive Acceleration_02 HW_ Lane-Centered Adaptive Follow_Excessive Acceleration_04 HW_ Lane-Centered Adaptive Follow_Excessive Deceleration_01 HW_ Lane-Centered Adaptive Follow_Excessive Deceleration_02 HW_ Lane-Centered Adaptive Follow_Excessive Deceleration_04 HW_ Lane-Centered Adaptive Follow_Insufficient Acceleration_01 HW_ Lane-Centered Adaptive Follow_Insufficient Acceleration_03 HW_ Lane-Centered Adaptive Follow_Insufficient Deceleration_01 HW_ Lane-Centered Adaptive Follow_Insufficient Deceleration_03 | K22: HFS-025, HFS-026
A23: LV-06 | B23: Leader qui accélère et s'éloigne | C23: URB-FOL | D23: justifié | E23: catalogue SERYTI | F23: Le HIRE de URB-FOL relie une déviation de commande sollicitée par la scène (Acceleration command, Deceleration command) au hazard de l'abstract (H2, H3) | G23: H2 Front collision, H3 Rear-end by follower | H23: Acceleration command, Deceleration command | I23: 20 | J23: URB_ Lane-Centered Adaptive Follow_Excessive Acceleration_01 URB_ Lane-Centered Adaptive Follow_Excessive Acceleration_02 URB_ Lane-Centered Adaptive Follow_Excessive Acceleration_04 URB_ Lane-Centered Adaptive Follow_Excessive Deceleration_01 URB_ Lane-Centered Adaptive Follow_Excessive Deceleration_02 URB_ Lane-Centered Adaptive Follow_Excessive Deceleration_04 URB_ Lane-Centered Adaptive Follow_Insufficient Acceleration_01 URB_ Lane-Centered Adaptive Follow_Insufficient Acceleration_03 URB_ Lane-Centered Adaptive Follow_Insufficient Deceleration_01 URB_ Lane-Centered Adaptive Follow_Insufficient Deceleration_03 | K23: HFS-071, HFS-072
A24: LV-07 | B24: Accordéon (stop-and-go) | C24: HW-FOL | D24: justifié | E24: catalogue SERYTI | F24: Le HIRE de HW-FOL relie une déviation de commande sollicitée par la scène (Acceleration command, Brake Lights command, Deceleration command) au hazard de l'abstract (H2, H3) | G24: H2 Front collision, H3 Rear-end by follower | H24: Acceleration command, Brake Lights command, Deceleration command | I24: 37 | J24: HW_ Lane-Centered Adaptive Follow_Brake Lights too late_01 HW_ Lane-Centered Adaptive Follow_Excessive Acceleration_01 HW_ Lane-Centered Adaptive Follow_Excessive Acceleration_02 HW_ Lane-Centered Adaptive Follow_Excessive Acceleration_04 HW_ Lane-Centered Adaptive Follow_Excessive Deceleration_01 HW_ Lane-Centered Adaptive Follow_Excessive Deceleration_02 HW_ Lane-Centered Adaptive Follow_Excessive Deceleration_04 HW_ Lane-Centered Adaptive Follow_Insufficient Acceleration_01 HW_ Lane-Centered Adaptive Follow_Insufficient Acceleration_03 HW_ Lane-Centered Adaptive Follow_Insufficient Deceleration_01 | K24: HFS-025, HFS-026
A25: LV-07 | B25: Accordéon (stop-and-go) | C25: URB-FOL | D25: justifié | E25: catalogue SERYTI | F25: Le HIRE de URB-FOL relie une déviation de commande sollicitée par la scène (Acceleration command, Deceleration command) au hazard de l'abstract (H2, H3) | G25: H2 Front collision, H3 Rear-end by follower | H25: Acceleration command, Brake Lights command, Deceleration command | I25: 20 | J25: URB_ Lane-Centered Adaptive Follow_Excessive Acceleration_01 URB_ Lane-Centered Adaptive Follow_Excessive Acceleration_02 URB_ Lane-Centered Adaptive Follow_Excessive Acceleration_04 URB_ Lane-Centered Adaptive Follow_Excessive Deceleration_01 URB_ Lane-Centered Adaptive Follow_Excessive Deceleration_02 URB_ Lane-Centered Adaptive Follow_Excessive Deceleration_04 URB_ Lane-Centered Adaptive Follow_Insufficient Acceleration_01 URB_ Lane-Centered Adaptive Follow_Insufficient Acceleration_03 URB_ Lane-Centered Adaptive Follow_Insufficient Deceleration_01 URB_ Lane-Centered Adaptive Follow_Insufficient Deceleration_03 | K25: HFS-071, HFS-072
